Workbook

Sheet Avg
A1: Avg. Semantic Percision | B1: BPMNChatbot++ | C1: XML Baseline | F1: Avg. Semantic Recall | G1: BPMNChatbot++ | H1: XML Baseline | K1: Avg. Semantic F1 | L1: BPMNChatbot++ | M1: XML Baseline
A2: 1 | B2: =AVERAGE('c1'!C1:E1) -> 92.307692 | C2: =AVERAGE('c1'!F1:H1) -> 91.666667 | F2: 1 | G2: =AVERAGE('c1'!C2:E2) -> 100 | H2: =AVERAGE('c1'!F2:H2) -> 100 | K2: 1 | L2: =2 * (B2 * G2) / (B2 + G2) -> 96 | M2: =2 * (C2 * H2) / (C2 + H2) -> 95.652174
A3: 2 | B3: =AVERAGE('c2'!C1:E1) -> 94.444444 | C3: =AVERAGE('c2'!F1:H1) -> 85.858586 | F3: 2 | G3: =AVERAGE('c2'!C2:E2) -> 100 | H3: =AVERAGE('c2'!F2:H2) -> 100 | K3: 2 | L3: =2 * (B3 * G3) / (B3 + G3) -> 97.142857 | M3: =2 * (C3 * H3) / (C3 + H3) -> 92.391304
A4: 3 | B4: =AVERAGE('c3'!C1:E1) -> 79.545455 | C4: =AVERAGE('c3'!F1:H1) -> 84.545455 | F4: 3 | G4: =AVERAGE('c3'!C2:E2) -> 100 | H4: =AVERAGE('c3'!F2:H2) -> 100 | K4: 3 | L4: =2 * (B4 * G4) / (B4 + G4) -> 88.607595 | M4: =2 * (C4 * H4) / (C4 + H4) -> 91.625616
A5: 4 | B5: =AVERAGE('c4'!C1:E1) -> 97.222222 | C5: =AVERAGE('c4'!F1:H1) -> 85.990338 | F5: 4 | G5: =AVERAGE('c4'!C2:E2) -> 100 | H5: =AVERAGE('c4'!F2:H2) -> 100 | K5: 4 | L5: =2 * (B5 * G5) / (B5 + G5) -> 98.591549 | M5: =2 * (C5 * H5) / (C5 + H5) -> 92.467532
A6: 5 | B6: =AVERAGE('c5'!C1:E1) -> 100 | C6: =AVERAGE('c5'!F1:H1) -> 95.238095 | F6: 5 | G6: =AVERAGE('c5'!C2:E2) -> 100 | H6: =AVERAGE('c5'!F2:H2) -> 100 | K6: 5 | L6: =2 * (B6 * G6) / (B6 + G6) -> 100 | M6: =2 * (C6 * H6) / (C6 + H6) -> 97.560976
A7: 6 | B7: =AVERAGE('c6'!C1:E1) -> 97.435897 | C7: =AVERAGE('c6'!F1:H1) -> 83.915344 | F7: 6 | G7: =AVERAGE('c6'!C2:E2) -> 85.714286 | H7: =AVERAGE('c6'!F2:H2) -> 92.857143 | K7: 6 | L7: =2 * (B7 * G7) / (B7 + G7) -> 91.2 | M7: =2 * (C7 * H7) / (C7 + H7) -> 88.160089
A8: 7 | B8: =AVERAGE('c7'!C1:E1) -> 98.765432 | C8: =AVERAGE('c7'!F1:H1) -> 98.550725 | F8: 7 | G8: =AVERAGE('c7'!C2:E2) -> 95.238095 | H8: =AVERAGE('c7'!F2:H2) -> 73.809524 | K8: 7 | L8: =2 * (B8 * G8) / (B8 + G8) -> 96.969697 | M8: =2 * (C8 * H8) / (C8 + H8) -> 84.404404
A9: 8 | B9: =AVERAGE('c8'!C1:E1) -> 95.034483 | C9: =AVERAGE('c8'!F1:H1) -> 89.170041 | F9: 8 | G9: =AVERAGE('c8'!C2:E2) -> 87.777778 | H9: =AVERAGE('c8'!F2:H2) -> 97.777778 | K9: 8 | L9: =2 * (B9 * G9) / (B9 + G9) -> 91.262103 | M9: =2 * (C9 * H9) / (C9 + H9) -> 93.275744
A10: 9 | B10: =AVERAGE('c9'!C1:E1) -> 100 | C10: =AVERAGE('c9'!F1:H1) -> 91.911765 | F10: 9 | G10: =AVERAGE('c9'!C2:E2) -> 100 | H10: =AVERAGE('c9'!F2:H2) -> 95.833333 | K10: 9 | L10: =2 * (B10 * G10) / (B10 + G10) -> 100 | M10: =2 * (C10 * H10) / (C10 + H10) -> 93.831593
A11: 10 | B11: =AVERAGE('c10'!C1:E1) -> 84.366472 | C11: =AVERAGE('c10'!F1:H1) -> 83.856209 | F11: 10 | G11: =AVERAGE('c10'!C2:E2) -> 100 | H11: =AVERAGE('c10'!F2:H2) -> 95.833333 | K11: 10 | L11: =2 * (B11 * G11) / (B11 + G11) -> 91.520406 | M11: =2 * (C11 * H11) / (C11 + H11) -> 89.445606
A12: 11 | B12: =AVERAGE('c11'!C1:E1) -> 100 | C12: =AVERAGE('c11'!F1:H1) -> 93.174603 | F12: 11 | G12: =AVERAGE('c11'!C2:E2) -> 93.75 | H12: =AVERAGE('c11'!F2:H2) -> 81.25 | K12: 11 | L12: =2 * (B12 * G12) / (B12 + G12) -> 96.774194 | M12: =2 * (C12 * H12) / (C12 + H12) -> 86.804687
A13: 12 | B13: =AVERAGE('c12'!C1:E1) -> 97.777778 | C13: =AVERAGE('c12'!F1:H1) -> 98.148148 | F13: 12 | G13: =AVERAGE('c12'!C2:E2) -> 94.252874 | H13: =AVERAGE('c12'!F2:H2) -> 62.068966 | K13: 12 | L13: =2 * (B13 * G13) / (B13 + G13) -> 95.982974 | M13: =2 * (C13 * H13) / (C13 + H13) -> 76.046234
A14: 13 | B14: =AVERAGE('c13'!C1:E1) -> 95.238095 | C14: =AVERAGE('c13'!F1:H1) -> 89.102564 | F14: 13 | G14: =AVERAGE('c13'!C2:E2) -> 70.588235 | H14: =AVERAGE('c13'!F2:H2) -> 70.588235 | K14: 13 | L14: =2 * (B14 * G14) / (B14 + G14) -> 81.081081 | M14: =2 * (C14 * H14) / (C14 + H14) -> 78.772137
A15: 14 | B15: =AVERAGE('c14'!C1:E1) -> 81.880952 | C15: =AVERAGE('c14'!F1:H1) -> 93.205128 | F15: 14 | G15: =AVERAGE('c14'!C2:E2) -> 100 | H15: =AVERAGE('c14'!F2:H2) -> 70.175439 | K15: 14 | L15: =2 * (B15 * G15) / (B15 + G15) -> 90.037963 | M15: =2 * (C15 * H15) / (C15 + H15) -> 80.067182
A16: 15 | B16: =AVERAGE('c15'!C1:E1) -> 100 | C16: =AVERAGE('c15'!F1:H1) -> 100 | F16: 15 | G16: =AVERAGE('c15'!C2:E2) -> 95.391533 | H16: =AVERAGE('c15'!F2:H2) -> 92.517628 | K16: 15 | L16: =2 * (B16 * G16) / (B16 + G16) -> 97.641419 | M16: =2 * (C16 * H16) / (C16 + H16) -> 96.113409
A17: 16 | B17: =AVERAGE('c16'!C1:E1) -> 97.346405 | C17: =AVERAGE('c16'!F1:H1) -> 99.29078 | F17: 16 | G17: =AVERAGE('c16'!C2:E2) -> 91.311437 | H17: =AVERAGE('c16'!F2:H2) -> 83.857442 | K17: 16 | L17: =2 * (B17 * G17) / (B17 + G17) -> 94.232395 | M17: =2 * (C17 * H17) / (C17 + H17) -> 90.923851
A19: Avg. Semantic Percision | B19: BPMNChatbot++ | C19: XML Baseline | F19: Avg. Semantic Recall | G19: BPMNChatbot++ | H19: XML Baseline | K19: Avg. Semantic F1 | L19: BPMNChatbot++ | M19: XML Baseline
A20: cluster 1 | B20: =AVERAGE(B2:B5) -> 90.879953 | C20: =AVERAGE(C2:C5) -> 87.015261 | F20: cluster 1 | G20: =AVERAGE(G2:G5) -> 100 | H20: =AVERAGE(H2:H5) -> 100 | K20: cluster 1 | L20: =2 * (B20 * G20) / (B20 + G20) -> 95.222103 | M20: =2 * (C20 * H20) / (C20 + H20) -> 93.056856
A21: cluster 2 | B21: =AVERAGE(B6:B9) -> 97.808953 | C21: =AVERAGE(C6:C9) -> 91.718551 | F21: cluster 2 | G21: =AVERAGE(G6:G9) -> 92.18254 | H21: =AVERAGE(H6:H9) -> 91.111111 | K21: cluster 2 | L21: =2 * (B21 * G21) / (B21 + G21) -> 94.912436 | M21: =2 * (C21 * H21) / (C21 + H21) -> 91.413822
A22: cluster 3 | B22: =AVERAGE(B10:B13) -> 95.536062 | C22: =AVERAGE(C10:C13) -> 91.772681 | F22: cluster 3 | G22: =AVERAGE(G10:G13) -> 97.000718 | H22: =AVERAGE(H10:H13) -> 83.746408 | K22: cluster 3 | L22: =2 * (B22 * G22) / (B22 + G22) -> 96.262819 | M22: =2 * (C22 * H22) / (C22 + H22) -> 87.576029
A23: cluster 4 | B23: =AVERAGE(B14:B17) -> 93.616363 | C23: =AVERAGE(C14:C17) -> 95.399618 | F23: cluster 4 | G23: =AVERAGE(G14:G17) -> 89.322801 | H23: =AVERAGE(H14:H17) -> 79.284686 | K23: cluster 4 | L23: =2 * (B23 * G23) / (B23 + G23) -> 91.419198 | M23: =2 * (C23 * H23) / (C23 + H23) -> 86.598837

Sheet Jaccard
E1: Avg Strict Jaccard Measure Chatbot runs | F1: Avg Strict Jaccard Measure XML runs | G1: Avg Strict Jaccard Measure Chatbot vs XML runs | H1: Avg Loose Jaccard Measure Chatbot runs | I1: Avg Loose Jaccard Measure XML runs | J1: Avg Loose Jaccard Measure Chatbot vs XML runs
D2: 1 | E2: =AVERAGE('c1'!K3, 'c1'!K4, 'c1'!L4) -> 0.78333333
D3: 2 | E3: =AVERAGE('c2'!K3, 'c2'!K4, 'c2'!L4) -> 0.86666667
D4: 3 | E4: =AVERAGE('c3'!K3, 'c3'!K4, 'c3'!L4) -> 0.91111111
A5: Avg Strict Jaccard Measure Chatbot runs | B5: =AVERAGE('c1:c16'!K3, 'c1:c16'!K4, 'c1:c16'!L4) -> 0.79502676 | D5: 4 | E5: =AVERAGE('c4'!K3, 'c4'!K4, 'c4'!L4) -> 0.71408046
A6: Avg Strict Jaccard Measure XML runs | B6: =AVERAGE('c1:c16'!N6, 'c1:c16'!N7, 'c1:c16'!O7) -> 0.64488943 | D6: 5 | E6: =AVERAGE('c5'!K3, 'c5'!K4, 'c5'!L4) -> 0.95555556
A7: Avg Strict Jaccard Measure Chatbot vs XML runs | B7: =AVERAGE('c1:c16'!K5:M7) -> 0.59604945 | D7: 6 | E7: =AVERAGE('c6'!K3, 'c6'!K4, 'c6'!L4) -> 0.86811966
D8: 7 | E8: =AVERAGE('c7'!K3, 'c7'!K4, 'c7'!L4) -> 0.64558306
A9: Avg Loose Jaccard Measure Chatbot runs | B9: =AVERAGE('c1:c16'!R3, 'c1:c16'!R4, 'c1:c16'!S4) -> 0.8161682 | D9: 8 | E9: =AVERAGE('c8'!K3, 'c8'!K4, 'c8'!L4) -> 0.63445596
A10: Avg Loose Jaccard Measure XML runs | B10: =AVERAGE('c1:c16'!U6, 'c1:c16'!U7, 'c1:c16'!V7) -> 0.70244017 | D10: 9 | E10: =AVERAGE('c9'!K3, 'c9'!K4, 'c9'!L4) -> 0.79541446
A11: Avg Loose Jaccard Measure Chatbot vs XML runs | B11: =AVERAGE('c1:c16'!R5:T7) -> 0.64139767 | D11: 10 | E11: =AVERAGE('c10'!K3, 'c10'!K4, 'c10'!L4) -> 0.87042316
D12: 11 | E12: =AVERAGE('c11'!K3, 'c11'!K4, 'c11'!L4) -> 0.96825397
D13: 12 | E13: =AVERAGE('c12'!K3, 'c12'!K4, 'c12'!L4) -> 0.76640299
D14: 13 | E14: =AVERAGE('c13'!K3, 'c13'!K4, 'c13'!L4) -> 0.52739215
D15: 14 | E15: =AVERAGE('c14'!K3, 'c14'!K4, 'c14'!L4) -> 0.78935574
D16: 15 | E16: =AVERAGE('c15'!K3, 'c15'!K4, 'c15'!L4) -> 0.84940572
D17: 16 | E17: =AVERAGE('c16'!K3, 'c16'!K4, 'c16'!L4) -> 0.77487419
D20: cluster 1 | E20: =AVERAGE('c1:c4'!K3, 'c1:c4'!K4, 'c1:c4'!L4) -> 0.81879789
D21: cluster 2 | E21: =AVERAGE('c5:c8'!K3,'c5:c8'!K4,'c5:c8'!L4) -> 0.77592856
D22: cluster 3 | E22: =AVERAGE('c9:c12'!K3, 'c9:c12'!K4, 'c9:c12'!L4) -> 0.85012364
D23: cluster 4 | E23: =AVERAGE('c13:c16'!K3, 'c13:c16'!K4, 'c13:c16'!L4) -> 0.73525695

Sheet Total (c1-c16)
B1: Chatbot | C1: XML
A2: Avg. Semantic Percision | B2: =AVERAGE('c1:c16'!C1:E1) -> 94.460333 | C2: =AVERAGE('c1:c16'!F1:H1) -> 91.476528
A3: Avg. Semantic Recall | B3: =AVERAGE('c1:c16'!C2:E2) -> 94.626515 | C3: =AVERAGE('c1:c16'!F2:H2) -> 88.535551
A5: Avg Strict Jaccard Measure Chatbot runs | B5: =AVERAGE('c1:c16'!K3, 'c1:c16'!K4, 'c1:c16'!L4) -> 0.79502676
A6: Avg Strict Jaccard Measure XML runs | B6: =AVERAGE('c1:c16'!N6, 'c1:c16'!N7, 'c1:c16'!O7) -> 0.64488943
A7: Avg Strict Jaccard Measure Chatbot vs XML runs | B7: =AVERAGE('c1:c16'!K5:M7) -> 0.59604945
A9: Avg Loose Jaccard Measure Chatbot runs | B9: =AVERAGE('c1:c16'!R3, 'c1:c16'!R4, 'c1:c16'!S4) -> 0.8161682
A10: Avg Loose Jaccard Measure XML runs | B10: =AVERAGE('c1:c16'!U6, 'c1:c16'!U7, 'c1:c16'!V7) -> 0.70244017
A11: Avg Loose Jaccard Measure Chatbot vs XML runs | B11: =AVERAGE('c1:c16'!R5:T7) -> 0.64139767

Sheet Total (c1-c12)
B1: Chatbot | C1: XML
A2: Avg. Semantic Percision | B2: =AVERAGE('c1:c12'!C1:E1) -> 94.741656 | C2: =AVERAGE('c1:c12'!F1:H1) -> 90.168831
A3: Avg. Semantic Recall | B3: =AVERAGE('c1:c12'!C2:E2) -> 96.394419 | C3: =AVERAGE('c1:c12'!F2:H2) -> 91.619173
A5: Avg Strict Jaccard Measure Chatbot runs | B5: =AVERAGE('c1:c12'!K3, 'c1:c12'!K4, 'c1:c12'!L4) -> 0.81495003
A6: Avg Strict Jaccard Measure XML runs | B6: =AVERAGE('c1:c12'!N6, 'c1:c12'!N7, 'c1:c12'!O7) -> 0.65316831
A7: Avg Strict Jaccard Measure Chatbot vs XML runs | B7: =AVERAGE('c1:c12'!K5:M7) -> 0.61825199
A9: Avg Loose Jaccard Measure Chatbot runs | B9: =AVERAGE('c1:c12'!R3, 'c1:c12'!R4, 'c1:c12'!S4) -> 0.84002699
A10: Avg Loose Jaccard Measure XML runs | B10: =AVERAGE('c1:c12'!U6, 'c1:c12'!U7, 'c1:c12'!V7) -> 0.70950305
A11: Avg Loose Jaccard Measure Chatbot vs XML runs | B11: =AVERAGE('c1:c12'!R5:T7) -> 0.65927859

Sheet Total (c13-c16)
B1: Chatbot | C1: XML
A2: Avg. Semantic Percision | B2: =AVERAGE('c13:c16'!C1:E1) -> 93.616363 | C2: =AVERAGE('c13:c16'!F1:H1) -> 95.399618
A3: Avg. Semantic Recall | B3: =AVERAGE('c13:c16'!C2:E2) -> 89.322801 | C3: =AVERAGE('c13:c16'!F2:H2) -> 79.284686
A5: Avg Strict Jaccard Measure Chatbot runs | B5: =AVERAGE('c13:c16'!K3, 'c13:c16'!K4, 'c13:c16'!L4) -> 0.73525695
A6: Avg Strict Jaccard Measure XML runs | B6: =AVERAGE('c13:c16'!N6, 'c13:c16'!N7, 'c13:c16'!O7) -> 0.62005278
A7: Avg Strict Jaccard Measure Chatbot vs XML runs | B7: =AVERAGE('c13:c16'!K5:M7) -> 0.52944182
A9: Avg Loose Jaccard Measure Chatbot runs | B9: =AVERAGE('c13:c16'!R3, 'c13:c16'!R4, 'c13:c16'!S4) -> 0.74459183
A10: Avg Loose Jaccard Measure XML runs | B10: =AVERAGE('c13:c16'!U6, 'c13:c16'!U7, 'c13:c16'!V7) -> 0.68125151
A11: Avg Loose Jaccard Measure Chatbot vs XML runs | B11: =AVERAGE('c13:c16'!R5:T7) -> 0.58775494

Sheet c1
A1: Semantic Percision | C1: =SUM(C3:C4) / (C3+ C4+ C7) * 100 -> 92.307692 | D1: =SUM(D3:D4) / (D3+ D4+ D7) * 100 -> 92.307692 | E1: =SUM(E3:E4) / (E3+ E4+ E7) * 100 -> 92.307692 | F1: =SUM(F3:F4) / (F3+ F4+ F7) * 100 -> 100 | G1: =SUM(G3:G4) / (G3+ G4+ G7) * 100 -> 75 | H1: =SUM(H3:H4) / (H3+ H4+ H7) * 100 -> 100 | J1: Jaccard Strict | K1: Chatbot run 1 | L1: Chatbot run 2 | M1: Chatbot run 3 | N1: XML run 1 | O1: XML run 2 | P1: XML run 3 | Q1: Jaccard Loose | R1: Chatbot run 1 | S1: Chatbot run 2 | T1: Chatbot run 3 | U1: XML run 1 | V1: XML run 2 | W1: XML run 3
A2: Semantic Recall | C2: =SUM(C3:C4) / SUM(C3:C5) *100 -> 100 | D2: =SUM(D3:D4) / SUM(D3:D5) *100 -> 100 | E2: =SUM(E3:E4) / SUM(E3:E5) *100 -> 100 | F2: =SUM(F3:F4) / SUM(F3:F5) *100 -> 100 | G2: =SUM(G3:G4) / SUM(G3:G5) *100 -> 100 | H2: =SUM(H3:H4) / SUM(H3:H5) *100 -> 100 | J2: Chatbot run 1 | Q2: Chatbot run 1
A3: Semantic TP Explicit | C3: =COUNTIF(C10:C21, 2) -> 11 | D3: =COUNTIF(D10:D21, 2) -> 11 | E3: =COUNTIF(E10:E21, 2) -> 11 | F3: =COUNTIF(F10:F21, 2) -> 12 | G3: =COUNTIF(G10:G21, 2) -> 11 | H3: =COUNTIF(H10:H21, 2) -> 12 | J3: Chatbot run 2 | K3: {=IFERROR(SUMPRODUCT((C10:C100<>"")*(D10:D100<>"")*(C10:C100=D10:D100))/SUMPRODUCT(--((C10:C100<>"")+(D10:D100<>"")>0)),"")} -> 0.85 | Q3: Chatbot run 2 | R3: {=IFERROR( SUMPRODUCT((C10:C100<>"")*(D10:D100<>"")* ((C10:C100=D10:D100)+((C10:C100=1)*(D10:D100=2))+((C10:C100=2)*(D10:D100=1)))) / SUMPRODUCT(--((C10:C100<>"")+(D10:D100<>"")>0)), "")} -> 0.85
A4: Semantic TP Implicit | C4: =COUNTIF(C10:C21, 1) -> 1 | D4: =COUNTIF(D10:D21, 1) -> 1 | E4: =COUNTIF(E10:E21, 1) -> 1 | F4: =COUNTIF(F10:F21, 1) -> 0 | G4: =COUNTIF(G10:G21, 1) -> 1 | H4: =COUNTIF(H10:H21, 1) -> 0 | J4: Chatbot run 3 | K4: {=IFERROR(SUMPRODUCT((C10:C100<>"")*(E10:E100<>"")*(C10:C100=E10:E100))/SUMPRODUCT(--((C10:C100<>"")+(E10:E100<>"")>0)),"")} -> 0.68181818 | L4: {=IFERROR(SUMPRODUCT((E10:E100<>"")*(D10:D100<>"")*(E10:E100=D10:D100))/SUMPRODUCT(--((E10:E100<>"")+(D10:D100<>"")>0)),"")} -> 0.81818182 | Q4: Chatbot run 3 | R4: {=IFERROR( SUMPRODUCT((C10:C100<>"")*(E10:E100<>"")* ((C10:C100=E10:E100)+((C10:C100=1)*(E10:E100=2))+((C10:C100=2)*(E10:E100=1)))) / SUMPRODUCT(--((C10:C100<>"")+(E10:E100<>"")>0)), "")} -> 0.77272727 | S4: {=IFERROR( SUMPRODUCT((E10:E100<>"")*(D10:D100<>"")* ((E10:E100=D10:D100)+((E10:E100=1)*(D10:D100=2))+((E10:E100=2)*(D10:D100=1)))) / SUMPRODUCT(--((E10:E100<>"")+(D10:D100<>"")>0)), "")} -> 0.90909091
A5: Semantic FN | C5: =COUNTIF(C10:C21, 0) -> 0 | D5: =COUNTIF(D10:D21, 0) -> 0 | E5: =COUNTIF(E10:E21, 0) -> 0 | F5: =COUNTIF(F10:F21, 0) -> 0 | G5: =COUNTIF(G10:G21, 0) -> 0 | H5: =COUNTIF(H10:H21, 0) -> 0 | J5: XML run 1 | K5: {=IFERROR(SUMPRODUCT((C10:C100<>"")*(F10:F100<>"")*(C10:C100=F10:F100))/SUMPRODUCT(--((C10:C100<>"")+(F10:F100<>"")>0)),"")} -> 0.63157895 | L5: {=IFERROR(SUMPRODUCT((F10:F100<>"")*(D10:D100<>"")*(F10:F100=D10:D100))/SUMPRODUCT(--((F10:F100<>"")+(D10:D100<>"")>0)),"")} -> 0.54545455 | M5: {=IFERROR(SUMPRODUCT((F10:F100<>"")*(E10:E100<>"")*(F10:F100=E10:E100))/SUMPRODUCT(--((F10:F100<>"")+(E10:E100<>"")>0)),"")} -> 0.5 | Q5: XML run 1 | R5: {=IFERROR( SUMPRODUCT((C10:C100<>"")*(F10:F100<>"")* ((C10:C100=F10:F100)+((C10:C100=1)*(F10:F100=2))+((C10:C100=2)*(F10:F100=1)))) / SUMPRODUCT(--((C10:C100<>"")+(F10:F100<>"")>0)), "")} -> 0.68421053 | S5: {=IFERROR( SUMPRODUCT((F10:F100<>"")*(D10:D100<>"")* ((F10:F100=D10:D100)+((F10:F100=1)*(D10:D100=2))+((F10:F100=2)*(D10:D100=1)))) / SUMPRODUCT(--((F10:F100<>"")+(D10:D100<>"")>0)), "")} -> 0.59090909 | T5: {=IFERROR( SUMPRODUCT((F10:F100<>"")*(E10:E100<>"")* ((F10:F100=E10:E100)+((F10:F100=1)*(E10:E100=2))+((F10:F100=2)*(E10:E100=1)))) / SUMPRODUCT(--((F10:F100<>"")+(E10:E100<>"")>0)), "")} -> 0.54166667
A6: Semantic FP Strict | C6: =COUNTIF(C23:C41,0) + COUNTIF(C23:C41,1) -> 5 | D6: =COUNTIF(D23:D41,0) + COUNTIF(D23:D41,1) -> 8 | E6: =COUNTIF(E23:E41,0) + COUNTIF(E23:E41,1) -> 10 | F6: =COUNTIF(F23:F41,0) + COUNTIF(F23:F41,1) -> 3 | G6: =COUNTIF(G23:G41,0) + COUNTIF(G23:G41,1) -> 6 | H6: =COUNTIF(H23:H41,0) + COUNTIF(H23:H41,1) -> 7 | J6: XML run 2 | K6: {=IFERROR(SUMPRODUCT((C10:C100<>"")*(G10:G100<>"")*(C10:C100=G10:G100))/SUMPRODUCT(--((C10:C100<>"")+(G10:G100<>"")>0)),"")} -> 0.5 | L6: {=SUMPRODUCT((D10:D100<>0)*(G10:G100<>0)) / SUMPRODUCT(((D10:D100<>0)+(G10:G100<>0)>0)*1)} -> 0.65 | M6: {=IFERROR(SUMPRODUCT((G10:G100<>"")*(E10:E100<>"")*(G10:G100=E10:E100))/SUMPRODUCT(--((G10:G100<>"")+(E10:E100<>"")>0)),"")} -> 0.48148148 | N6: {=IFERROR(SUMPRODUCT((G10:G100<>"")*(F10:F100<>"")*(G10:G100=F10:F100))/SUMPRODUCT(--((G10:G100<>"")+(F10:F100<>"")>0)),"")} -> 0.6 | Q6: XML run 2 | R6: {=IFERROR( SUMPRODUCT((C10:C100<>"")*(G10:G100<>"")* ((C10:C100=G10:G100)+((C10:C100=1)*(G10:G100=2))+((C10:C100=2)*(G10:G100=1)))) / SUMPRODUCT(--((C10:C100<>"")+(G10:G100<>"")>0)), "")} -> 0.59090909 | S6: {=IFERROR( SUMPRODUCT((D10:D100<>"")*(G10:G100<>"")* ((D10:D100=G10:G100)+((D10:D100=1)*(G10:G100=2))+((D10:D100=2)*(G10:G100=1)))) / SUMPRODUCT(--((D10:D100<>"")+(G10:G100<>"")>0)), "")} -> 0.52 | T6: {=IFERROR( SUMPRODUCT((G10:G100<>"")*(E10:E100<>"")* ((G10:G100=E10:E100)+((G10:G100=1)*(E10:E100=2))+((G10:G100=2)*(E10:E100=1)))) / SUMPRODUCT(--((G10:G100<>"")+(E10:E100<>"")>0)), "")} -> 0.48148148 | U6: {=IFERROR( SUMPRODUCT((F10:F100<>"")*(G10:G100<>"")* ((F10:F100=G10:G100)+((F10:F100=1)*(G10:G100=2))+((F10:F100=2)*(G10:G100=1)))) / SUMPRODUCT(--((F10:F100<>"")+(G10:G100<>"")>0)), "")} -> 0.65
A7: Semantic FP Loose | C7: =COUNTIF(C23:C41,0) -> 1 | D7: =COUNTIF(D23:D41,0) -> 1 | E7: =COUNTIF(E23:E41,0) -> 1 | F7: =COUNTIF(F23:F41,0) -> 0 | G7: =COUNTIF(G23:G41,0) -> 4 | H7: =COUNTIF(H23:H41,0) -> 0 | J7: XML run 3 | K7: {=IFERROR(SUMPRODUCT((C10:C100<>"")*(H10:H100<>"")*(C10:C100=H10:H100))/SUMPRODUCT(--((C10:C100<>"")+(H10:H100<>"")>0)),"")} -> 0.75 | L7: {=IFERROR(SUMPRODUCT((H10:H100<>"")*(D10:D100<>"")*(H10:H100=D10:D100))/SUMPRODUCT(--((H10:H100<>"")+(D10:D100<>"")>0)),"")} -> 0.72727273 | M7: {=IFERROR(SUMPRODUCT((H10:H100<>"")*(E10:E100<>"")*(H10:H100=E10:E100))/SUMPRODUCT(--((H10:H100<>"")+(E10:E100<>"")>0)),"")} -> 0.66666667 | N7: {=IFERROR(SUMPRODUCT((F10:F100<>"")*(H10:H100<>"")*(F10:F100=H10:H100))/SUMPRODUCT(--((F10:F100<>"")+(H10:H100<>"")>0)),"")} -> 0.61904762 | O7: {=IFERROR(SUMPRODUCT((G10:G100<>"")*(H10:H100<>"")*(G10:G100=H10:H100))/SUMPRODUCT(--((G10:G100<>"")+(H10:H100<>"")>0)),"")} -> 0.5 | Q7: XML run 3 | R7: {=IFERROR( SUMPRODUCT((C10:C100<>"")*(H10:H100<>"")* ((C10:C100=H10:H100)+((C10:C100=1)*(H10:H100=2))+((C10:C100=2)*(H10:H100=1)))) / SUMPRODUCT(--((C10:C100<>"")+(H10:H100<>"")>0)), "")} -> 0.8 | S7: {=IFERROR( SUMPRODUCT((H10:H100<>"")*(D10:D100<>"")* ((H10:H100=D10:D100)+((H10:H100=1)*(D10:D100=2))+((H10:H100=2)*(D10:D100=1)))) / SUMPRODUCT(--((H10:H100<>"")+(D10:D100<>"")>0)), "")} -> 0.77272727 | T7: {=IFERROR( SUMPRODUCT((H10:H100<>"")*(E10:E100<>"")* ((H10:H100=E10:E100)+((H10:H100=1)*(E10:E100=2))+((H10:H100=2)*(E10:E100=1)))) / SUMPRODUCT(--((H10:H100<>"")+(E10:E100<>"")>0)), "")} -> 0.70833333 | U7: {=IFERROR( SUMPRODUCT((F10:F100<>"")*(H10:H100<>"")* ((F10:F100=H10:H100)+((F10:F100=1)*(H10:H100=2))+((F10:F100=2)*(H10:H100=1)))) / SUMPRODUCT(--((F10:F100<>"")+(H10:H100<>"")>0)), "")} -> 0.61904762 | V7: {=IFERROR( SUMPRODUCT((H10:H100<>"")*(G10:G100<>"")* ((H10:H100=G10:G100)+((H10:H100=1)*(G10:G100=2))+((H10:H100=2)*(G10:G100=1)))) / SUMPRODUCT(--((H10:H100<>"")+(G10:G100<>"")>0)), "")} -> 0.54166667
C9: Chatbot run 1 | D9: Chatbot run 2 | E9: Chatbot run 3 | F9: XML run 1 | G9: XML run 2 | H9: XML run 3
A10: Pools | B10: Bank | C10: 2 | D10: 2 | E10: 2 | F10: 2 | G10: 2 | H10: 2
B11: Customer | C11: 1 | D11: 1 | E11: 2 | F11: 2 | G11: 2 | H11: 2
A12: Tasks/Messages/Events | B12: Receive Application | C12: 2 | D12: 2 | E12: 2 | F12: 2 | G12: 2 | H12: 2
B13: Evaluate Application | C13: 2 | D13: 2 | E13: 2 | F13: 2 | G13: 2 | H13: 2
B14: Notify Customer | C14: 2 | D14: 2 | E14: 2 | F14: 2 | G14: 2 | H14: 2
B15: Create Account | C15: 2 | D15: 2 | E15: 2 | F15: 2 | G15: 2 | H15: 2
B16: Send Welcome Pack | C16: 2 | D16: 2 | E16: 2 | F16: 2 | G16: 2 | H16: 2
B17: Send Bank Card | C17: 2 | D17: 2 | E17: 2 | F17: 2 | G17: 2 | H17: 2
B18: Send PIN | C18: 2 | D18: 2 | E18: 2 | F18: 2 | G18: 2 | H18: 2
A19: Conditions/Loops/Parallel: | B19: x Is application rejected? | C19: 2 | D19: 2 | E19: 2 | F19: 2 | G19: 2 | H19: 2
A20: Data Objects | B20: Application Form | C20: 2 | D20: 2 | E20: 2 | F20: 2 | G20: 2 | H20: 2
B21: Account | C21: 2 | D21: 2 | E21: 1 | F21: 2 | G21: 1 | H21: 2
A23: False Positives | B23: Account Opening Department Lane | C23: 0 | D23: 0 | E23: 0
B24: Parallel GW | C24: 1 | D24: 1 | E24: 1 | F24: 1 | G24: 1 | H24: 1
B25: Welcome Pack DO | C25: 1 | D25: 1 | E25: 1 | H25: 1
B26: Bank Card DO | C26: 1 | D26: 1 | E26: 1 | H26: 1
B27: PIN Number DO | C27: 1 | D27: 1 | E27: 1 | H27: 1
B28: Prepare Welcome Pack | D28: 1 | E28: 1 | H28: 1
B29: Prepare Bank card | D29: 1 | E29: 1
B30: Prepare PIN | D30: 1 | E30: 1
B31: Prepare Rejection Email | E31: 1
B32: Receive Notification from Bank | E32: 1
B33: Customer Service Lane | F33: 1
B34: Operations Lane | F34: 1
B35: Bank Back Office | G35: 1
B36: Second Send Rejection Notification | G36: 0
B37: Second Send Welcome Pack | G37: 0
B38: Second Send Bank card | G38: 0
B39: Second Send PIN | G39: 0
B40: Application Processing Lane | H40: 1
B41: Account Services Lane | H41: 1

Sheet c2
A1: Semantic Percision | C1: =SUM(C3:C4) / (C3+ C4+ C7) * 100 -> 100 | D1: =SUM(D3:D4) / (D3+ D4+ D7) * 100 -> 83.333333 | E1: =SUM(E3:E4) / (E3+ E4+ E7) * 100 -> 100 | F1: =SUM(F3:F4) / (F3+ F4+ F7) * 100 -> 83.333333 | G1: =SUM(G3:G4) / (G3+ G4+ G7) * 100 -> 83.333333 | H1: =SUM(H3:H4) / (H3+ H4+ H7) * 100 -> 90.909091 | J1: Jaccard Strict | K1: Chatbot run 1 | L1: Chatbot run 2 | M1: Chatbot run 3 | N1: XML run 1 | O1: XML run 2 | P1: XML run 3 | Q1: Jaccard Loose | R1: Chatbot run 1 | S1: Chatbot run 2 | T1: Chatbot run 3 | U1: XML run 1 | V1: XML run 2 | W1: XML run 3
A2: Semantic Recall | C2: =SUM(C3:C4) / SUM(C3:C5) *100 -> 100 | D2: =SUM(D3:D4) / SUM(D3:D5) *100 -> 100 | E2: =SUM(E3:E4) / SUM(E3:E5) *100 -> 100 | F2: =SUM(F3:F4) / SUM(F3:F5) *100 -> 100 | G2: =SUM(G3:G4) / SUM(G3:G5) *100 -> 100 | H2: =SUM(H3:H4) / SUM(H3:H5) *100 -> 100 | J2: Chatbot run 1 | Q2: Chatbot run 1
A3: Semantic TP Explicit | C3: =COUNTIF(C10:C19, 2) -> 10 | D3: =COUNTIF(D10:D19, 2) -> 10 | E3: =COUNTIF(E10:E19, 2) -> 10 | F3: =COUNTIF(F10:F19, 2) -> 8 | G3: =COUNTIF(G10:G19, 2) -> 9 | H3: =COUNTIF(H10:H19, 2) -> 10 | J3: Chatbot run 2 | K3: {=IFERROR(SUMPRODUCT((C10:C100<>"")*(D10:D100<>"")*(C10:C100=D10:D100))/SUMPRODUCT(--((C10:C100<>"")+(D10:D100<>"")>0)),"")} -> 0.8 | Q3: Chatbot run 2 | R3: {=IFERROR( SUMPRODUCT((C10:C100<>"")*(D10:D100<>"")* ((C10:C100=D10:D100)+((C10:C100=1)*(D10:D100=2))+((C10:C100=2)*(D10:D100=1)))) / SUMPRODUCT(--((C10:C100<>"")+(D10:D100<>"")>0)), "")} -> 0.8
A4: Semantic TP Implicit | C4: =COUNTIF(C10:C19, 1) -> 0 | D4: =COUNTIF(D10:D19, 1) -> 0 | E4: =COUNTIF(E10:E19, 1) -> 0 | F4: =COUNTIF(F10:F19, 1) -> 2 | G4: =COUNTIF(G10:G19, 1) -> 1 | H4: =COUNTIF(H10:H19, 1) -> 0 | J4: Chatbot run 3 | K4: {=IFERROR(SUMPRODUCT((C10:C100<>"")*(E10:E100<>"")*(C10:C100=E10:E100))/SUMPRODUCT(--((C10:C100<>"")+(E10:E100<>"")>0)),"")} -> 1 | L4: {=IFERROR(SUMPRODUCT((E10:E100<>"")*(D10:D100<>"")*(E10:E100=D10:D100))/SUMPRODUCT(--((E10:E100<>"")+(D10:D100<>"")>0)),"")} -> 0.8 | Q4: Chatbot run 3 | R4: {=IFERROR( SUMPRODUCT((C10:C100<>"")*(E10:E100<>"")* ((C10:C100=E10:E100)+((C10:C100=1)*(E10:E100=2))+((C10:C100=2)*(E10:E100=1)))) / SUMPRODUCT(--((C10:C100<>"")+(E10:E100<>"")>0)), "")} -> 1 | S4: {=IFERROR( SUMPRODUCT((E10:E100<>"")*(D10:D100<>"")* ((E10:E100=D10:D100)+((E10:E100=1)*(D10:D100=2))+((E10:E100=2)*(D10:D100=1)))) / SUMPRODUCT(--((E10:E100<>"")+(D10:D100<>"")>0)), "")} -> 0.8
A5: Semantic FN | C5: =COUNTIF(C10:C19, 0) -> 0 | D5: =COUNTIF(D10:D19, 0) -> 0 | E5: =COUNTIF(E10:E19, 0) -> 0 | F5: =COUNTIF(F10:F19, 0) -> 0 | G5: =COUNTIF(G10:G19, 0) -> 0 | H5: =COUNTIF(H10:H19, 0) -> 0 | J5: XML run 1 | K5: {=IFERROR(SUMPRODUCT((C10:C100<>"")*(F10:F100<>"")*(C10:C100=F10:F100))/SUMPRODUCT(--((C10:C100<>"")+(F10:F100<>"")>0)),"")} -> 0.53333333 | L5: {=IFERROR(SUMPRODUCT((F10:F100<>"")*(D10:D100<>"")*(F10:F100=D10:D100))/SUMPRODUCT(--((F10:F100<>"")+(D10:D100<>"")>0)),"")} -> 0.71428571 | M5: {=IFERROR(SUMPRODUCT((F10:F100<>"")*(E10:E100<>"")*(F10:F100=E10:E100))/SUMPRODUCT(--((F10:F100<>"")+(E10:E100<>"")>0)),"")} -> 0.53333333 | Q5: XML run 1 | R5: {=IFERROR( SUMPRODUCT((C10:C100<>"")*(F10:F100<>"")* ((C10:C100=F10:F100)+((C10:C100=1)*(F10:F100=2))+((C10:C100=2)*(F10:F100=1)))) / SUMPRODUCT(--((C10:C100<>"")+(F10:F100<>"")>0)), "")} -> 0.66666667 | S5: {=IFERROR( SUMPRODUCT((F10:F100<>"")*(D10:D100<>"")* ((F10:F100=D10:D100)+((F10:F100=1)*(D10:D100=2))+((F10:F100=2)*(D10:D100=1)))) / SUMPRODUCT(--((F10:F100<>"")+(D10:D100<>"")>0)), "")} -> 0.85714286 | T5: {=IFERROR( SUMPRODUCT((F10:F100<>"")*(E10:E100<>"")* ((F10:F100=E10:E100)+((F10:F100=1)*(E10:E100=2))+((F10:F100=2)*(E10:E100=1)))) / SUMPRODUCT(--((F10:F100<>"")+(E10:E100<>"")>0)), "")} -> 0.66666667
A6: Semantic FP Strict | C6: =COUNTIF(C21:C41,0) + COUNTIF(C21:C41,1) -> 3 | D6: =COUNTIF(D21:D41,0) + COUNTIF(D21:D41,1) -> 4 | E6: =COUNTIF(E21:E41,0) + COUNTIF(E21:E41,1) -> 3 | F6: =COUNTIF(F21:F41,0) + COUNTIF(F21:F41,1) -> 2 | G6: =COUNTIF(G21:G41,0) + COUNTIF(G21:G41,1) -> 3 | H6: =COUNTIF(H21:H41,0) + COUNTIF(H21:H41,1) -> 2 | J6: XML run 2 | K6: {=IFERROR(SUMPRODUCT((C10:C100<>"")*(G10:G100<>"")*(C10:C100=G10:G100))/SUMPRODUCT(--((C10:C100<>"")+(G10:G100<>"")>0)),"")} -> 0.5625 | L6: {=SUMPRODUCT((D10:D100<>0)*(G10:G100<>0)) / SUMPRODUCT(((D10:D100<>0)+(G10:G100<>0)>0)*1)} -> 0.76923077 | M6: {=IFERROR(SUMPRODUCT((G10:G100<>"")*(E10:E100<>"")*(G10:G100=E10:E100))/SUMPRODUCT(--((G10:G100<>"")+(E10:E100<>"")>0)),"")} -> 0.5625 | N6: {=IFERROR(SUMPRODUCT((G10:G100<>"")*(F10:F100<>"")*(G10:G100=F10:F100))/SUMPRODUCT(--((G10:G100<>"")+(F10:F100<>"")>0)),"")} -> 0.84615385 | Q6: XML run 2 | R6: {=IFERROR( SUMPRODUCT((C10:C100<>"")*(G10:G100<>"")* ((C10:C100=G10:G100)+((C10:C100=1)*(G10:G100=2))+((C10:C100=2)*(G10:G100=1)))) / SUMPRODUCT(--((C10:C100<>"")+(G10:G100<>"")>0)), "")} -> 0.625 | S6: {=IFERROR( SUMPRODUCT((D10:D100<>"")*(G10:G100<>"")* ((D10:D100=G10:G100)+((D10:D100=1)*(G10:G100=2))+((D10:D100=2)*(G10:G100=1)))) / SUMPRODUCT(--((D10:D100<>"")+(G10:G100<>"")>0)), "")} -> 0.8 | T6: {=IFERROR( SUMPRODUCT((G10:G100<>"")*(E10:E100<>"")* ((G10:G100=E10:E100)+((G10:G100=1)*(E10:E100=2))+((G10:G100=2)*(E10:E100=1)))) / SUMPRODUCT(--((G10:G100<>"")+(E10:E100<>"")>0)), "")} -> 0.625 | U6: {=IFERROR( SUMPRODUCT((F10:F100<>"")*(G10:G100<>"")* ((F10:F100=G10:G100)+((F10:F100=1)*(G10:G100=2))+((F10:F100=2)*(G10:G100=1)))) / SUMPRODUCT(--((F10:F100<>"")+(G10:G100<>"")>0)), "")} -> 0.92307692
A7: Semantic FP Loose | C7: =COUNTIF(C21:C41,0) -> 0 | D7: =COUNTIF(D21:D41,0) -> 2 | E7: =COUNTIF(E21:E41,0) -> 0 | F7: =COUNTIF(F21:F41,0) -> 2 | G7: =COUNTIF(G21:G41,0) -> 2 | H7: =COUNTIF(H21:H41,0) -> 1 | J7: XML run 3 | K7: {=IFERROR(SUMPRODUCT((C10:C100<>"")*(H10:H100<>"")*(C10:C100=H10:H100))/SUMPRODUCT(--((C10:C100<>"")+(H10:H100<>"")>0)),"")} -> 0.71428571 | L7: {=IFERROR(SUMPRODUCT((H10:H100<>"")*(D10:D100<>"")*(H10:H100=D10:D100))/SUMPRODUCT(--((H10:H100<>"")+(D10:D100<>"")>0)),"")} -> 0.66666667 | M7: {=IFERROR(SUMPRODUCT((H10:H100<>"")*(E10:E100<>"")*(H10:H100=E10:E100))/SUMPRODUCT(--((H10:H100<>"")+(E10:E100<>"")>0)),"")} -> 0.71428571 | N7: {=IFERROR(SUMPRODUCT((F10:F100<>"")*(H10:H100<>"")*(F10:F100=H10:H100))/SUMPRODUCT(--((F10:F100<>"")+(H10:H100<>"")>0)),"")} -> 0.57142857 | O7: {=IFERROR(SUMPRODUCT((G10:G100<>"")*(H10:H100<>"")*(G10:G100=H10:H100))/SUMPRODUCT(--((G10:G100<>"")+(H10:H100<>"")>0)),"")} -> 0.71428571 | Q7: XML run 3 | R7: {=IFERROR( SUMPRODUCT((C10:C100<>"")*(H10:H100<>"")* ((C10:C100=H10:H100)+((C10:C100=1)*(H10:H100=2))+((C10:C100=2)*(H10:H100=1)))) / SUMPRODUCT(--((C10:C100<>"")+(H10:H100<>"")>0)), "")} -> 0.71428571 | S7: {=IFERROR( SUMPRODUCT((H10:H100<>"")*(D10:D100<>"")* ((H10:H100=D10:D100)+((H10:H100=1)*(D10:D100=2))+((H10:H100=2)*(D10:D100=1)))) / SUMPRODUCT(--((H10:H100<>"")+(D10:D100<>"")>0)), "")} -> 0.66666667 | T7: {=IFERROR( SUMPRODUCT((H10:H100<>"")*(E10:E100<>"")* ((H10:H100=E10:E100)+((H10:H100=1)*(E10:E100=2))+((H10:H100=2)*(E10:E100=1)))) / SUMPRODUCT(--((H10:H100<>"")+(E10:E100<>"")>0)), "")} -> 0.71428571 | U7: {=IFERROR( SUMPRODUCT((F10:F100<>"")*(H10:H100<>"")* ((F10:F100=H10:H100)+((F10:F100=1)*(H10:H100=2))+((F10:F100=2)*(H10:H100=1)))) / SUMPRODUCT(--((F10:F100<>"")+(H10:H100<>"")>0)), "")} -> 0.71428571 | V7: {=IFERROR( SUMPRODUCT((H10:H100<>"")*(G10:G100<>"")* ((H10:H100=G10:G100)+((H10:H100=1)*(G10:G100=2))+((H10:H100=2)*(G10:G100=1)))) / SUMPRODUCT(--((H10:H100<>"")+(G10:G100<>"")>0)), "")} -> 0.78571429
C9: Chatbot run 1 | D9: Chatbot run 2 | E9: Chatbot run 3 | F9: XML run 1 | G9: XML run 2 | H9: XML run 3
A10: Pools | B10: Management | C10: 2 | D10: 2 | E10: 2 | F10: 2 | G10: 2 | H10: 2
B11: Accountant | C11: 2 | D11: 2 | E11: 2 | F11: 2 | G11: 2 | H11: 2
A12: Tasks/Messages/Events | B12: Order Cash-out Report | C12: 2 | D12: 2 | E12: 2 | F12: 2 | G12: 2 | H12: 2
B13: Filter Cash Transactions | C13: 2 | D13: 2 | E13: 2 | F13: 2 | G13: 2 | H13: 2
B14: Print Cash-out Report | C14: 2 | D14: 2 | E14: 2 | F14: 2 | G14: 2 | H14: 2
B15: Give Report to Management | C15: 2 | D15: 2 | E15: 2 | F15: 2 | G15: 2 | H15: 2
A16: Conditions/Loops/Parallel: | B16: Is Query Not Empty? | C16: 2 | D16: 2 | E16: 2 | F16: 2 | G16: 2 | H16: 2
A17: Data Objects | B17: Cash Database | C17: 2 | D17: 2 | E17: 2 | F17: 2 | G17: 2 | H17: 2
B18: Cash Transactions | C18: 2 | D18: 2 | E18: 2 | F18: 1 | G18: 2 | H18: 2
B19: Cash-out Report | C19: 2 | D19: 2 | E19: 2 | F19: 1 | G19: 1 | H19: 2
A21: False Positives | B21: Management Pool | D21: 0 | F21: 0 | G21: 0
B22: Accountant Pool | D22: 0 | F22: 0 | G22: 0
B23: Send Year and Month / Receive Year and Month | G23: 1 | H23: 1
B24: Year and Month DO | C24: 1 | D24: 1 | E24: 1 | H24: 0
B25: Wait for Report Order
B26: Company Pool | C26: 1 | E26: 1
B27: Specify Year and Month | C27: 1 | D27: 1 | E27: 1

Sheet c3
A1: Semantic Percision | C1: =SUM(C3:C4) / (C3+ C4+ C7) * 100 -> 81.818182 | D1: =SUM(D3:D4) / (D3+ D4+ D7) * 100 -> 75 | E1: =SUM(E3:E4) / (E3+ E4+ E7) * 100 -> 81.818182 | F1: =SUM(F3:F4) / (F3+ F4+ F7) * 100 -> 81.818182 | G1: =SUM(G3:G4) / (G3+ G4+ G7) * 100 -> 81.818182 | H1: =SUM(H3:H4) / (H3+ H4+ H7) * 100 -> 90 | J1: Jaccard Strict | K1: Chatbot run 1 | L1: Chatbot run 2 | M1: Chatbot run 3 | N1: XML run 1 | O1: XML run 2 | P1: XML run 3 | Q1: Jaccard Loose | R1: Chatbot run 1 | S1: Chatbot run 2 | T1: Chatbot run 3 | U1: XML run 1 | V1: XML run 2 | W1: XML run 3
A2: Semantic Recall | C2: =SUM(C3:C4) / SUM(C3:C5) *100 -> 100 | D2: =SUM(D3:D4) / SUM(D3:D5) *100 -> 100 | E2: =SUM(E3:E4) / SUM(E3:E5) *100 -> 100 | F2: =SUM(F3:F4) / SUM(F3:F5) *100 -> 100 | G2: =SUM(G3:G4) / SUM(G3:G5) *100 -> 100 | H2: =SUM(H3:H4) / SUM(H3:H5) *100 -> 100 | J2: Chatbot run 1 | Q2: Chatbot run 1
A3: Semantic TP Explicit | C3: =COUNTIF(C10:C18, 2) -> 9 | D3: =COUNTIF(D10:D18, 2) -> 9 | E3: =COUNTIF(E10:E18, 2) -> 9 | F3: =COUNTIF(F10:F18, 2) -> 9 | G3: =COUNTIF(G10:G18, 2) -> 7 | H3: =COUNTIF(H10:H18, 2) -> 8 | J3: Chatbot run 2 | K3: {=IFERROR(SUMPRODUCT((C10:C100<>"")*(D10:D100<>"")*(C10:C100=D10:D100))/SUMPRODUCT(--((C10:C100<>"")+(D10:D100<>"")>0)),"")} -> 0.93333333 | Q3: Chatbot run 2 | R3: {=IFERROR( SUMPRODUCT((C10:C100<>"")*(D10:D100<>"")* ((C10:C100=D10:D100)+((C10:C100=1)*(D10:D100=2))+((C10:C100=2)*(D10:D100=1)))) / SUMPRODUCT(--((C10:C100<>"")+(D10:D100<>"")>0)), "")} -> 0.93333333
A4: Semantic TP Implicit | C4: =COUNTIF(C10:C18, 1) -> 0 | D4: =COUNTIF(D10:D18, 1) -> 0 | E4: =COUNTIF(E10:E18, 1) -> 0 | F4: =COUNTIF(F10:F18, 1) -> 0 | G4: =COUNTIF(G10:G18, 1) -> 2 | H4: =COUNTIF(H10:H18, 1) -> 1 | J4: Chatbot run 3 | K4: {=IFERROR(SUMPRODUCT((C10:C100<>"")*(E10:E100<>"")*(C10:C100=E10:E100))/SUMPRODUCT(--((C10:C100<>"")+(E10:E100<>"")>0)),"")} -> 0.86666667 | L4: {=IFERROR(SUMPRODUCT((E10:E100<>"")*(D10:D100<>"")*(E10:E100=D10:D100))/SUMPRODUCT(--((E10:E100<>"")+(D10:D100<>"")>0)),"")} -> 0.93333333 | Q4: Chatbot run 3 | R4: {=IFERROR( SUMPRODUCT((C10:C100<>"")*(E10:E100<>"")* ((C10:C100=E10:E100)+((C10:C100=1)*(E10:E100=2))+((C10:C100=2)*(E10:E100=1)))) / SUMPRODUCT(--((C10:C100<>"")+(E10:E100<>"")>0)), "")} -> 0.86666667 | S4: {=IFERROR( SUMPRODUCT((E10:E100<>"")*(D10:D100<>"")* ((E10:E100=D10:D100)+((E10:E100=1)*(D10:D100=2))+((E10:E100=2)*(D10:D100=1)))) / SUMPRODUCT(--((E10:E100<>"")+(D10:D100<>"")>0)), "")} -> 0.93333333
A5: Semantic FN | C5: =COUNTIF(C10:C18, 0) -> 0 | D5: =COUNTIF(D10:D18, 0) -> 0 | E5: =COUNTIF(E10:E18, 0) -> 0 | F5: =COUNTIF(F10:F18, 0) -> 0 | G5: =COUNTIF(G10:G18, 0) -> 0 | H5: =COUNTIF(H10:H18, 0) -> 0 | J5: XML run 1 | K5: {=IFERROR(SUMPRODUCT((C10:C100<>"")*(F10:F100<>"")*(C10:C100=F10:F100))/SUMPRODUCT(--((C10:C100<>"")+(F10:F100<>"")>0)),"")} -> 0.875 | L5: {=IFERROR(SUMPRODUCT((F10:F100<>"")*(D10:D100<>"")*(F10:F100=D10:D100))/SUMPRODUCT(--((F10:F100<>"")+(D10:D100<>"")>0)),"")} -> 0.82352941 | M5: {=IFERROR(SUMPRODUCT((F10:F100<>"")*(E10:E100<>"")*(F10:F100=E10:E100))/SUMPRODUCT(--((F10:F100<>"")+(E10:E100<>"")>0)),"")} -> 0.76470588 | Q5: XML run 1 | R5: {=IFERROR( SUMPRODUCT((C10:C100<>"")*(F10:F100<>"")* ((C10:C100=F10:F100)+((C10:C100=1)*(F10:F100=2))+((C10:C100=2)*(F10:F100=1)))) / SUMPRODUCT(--((C10:C100<>"")+(F10:F100<>"")>0)), "")} -> 0.875 | S5: {=IFERROR( SUMPRODUCT((F10:F100<>"")*(D10:D100<>"")* ((F10:F100=D10:D100)+((F10:F100=1)*(D10:D100=2))+((F10:F100=2)*(D10:D100=1)))) / SUMPRODUCT(--((F10:F100<>"")+(D10:D100<>"")>0)), "")} -> 0.82352941 | T5: {=IFERROR( SUMPRODUCT((F10:F100<>"")*(E10:E100<>"")* ((F10:F100=E10:E100)+((F10:F100=1)*(E10:E100=2))+((F10:F100=2)*(E10:E100=1)))) / SUMPRODUCT(--((F10:F100<>"")+(E10:E100<>"")>0)), "")} -> 0.76470588
A6: Semantic FP Strict | C6: =COUNTIF(C20:C56,0) + COUNTIF(C20:C56,1) -> 5 | D6: =COUNTIF(D20:D56,0) + COUNTIF(D20:D56,1) -> 6 | E6: =COUNTIF(E20:E56,0) + COUNTIF(E20:E56,1) -> 5 | F6: =COUNTIF(F20:F56,0) + COUNTIF(F20:F56,1) -> 7 | G6: =COUNTIF(G20:G56,0) + COUNTIF(G20:G56,1) -> 5 | H6: =COUNTIF(H20:H56,0) + COUNTIF(H20:H56,1) -> 6 | J6: XML run 2 | K6: {=IFERROR(SUMPRODUCT((C10:C100<>"")*(G10:G100<>"")*(C10:C100=G10:G100))/SUMPRODUCT(--((C10:C100<>"")+(G10:G100<>"")>0)),"")} -> 0.73333333 | L6: {=SUMPRODUCT((D10:D100<>0)*(G10:G100<>0)) / SUMPRODUCT(((D10:D100<>0)+(G10:G100<>0)>0)*1)} -> 1 | M6: {=IFERROR(SUMPRODUCT((G10:G100<>"")*(E10:E100<>"")*(G10:G100=E10:E100))/SUMPRODUCT(--((G10:G100<>"")+(E10:E100<>"")>0)),"")} -> 0.73333333 | N6: {=IFERROR(SUMPRODUCT((G10:G100<>"")*(F10:F100<>"")*(G10:G100=F10:F100))/SUMPRODUCT(--((G10:G100<>"")+(F10:F100<>"")>0)),"")} -> 0.64705882 | Q6: XML run 2 | R6: {=IFERROR( SUMPRODUCT((C10:C100<>"")*(G10:G100<>"")* ((C10:C100=G10:G100)+((C10:C100=1)*(G10:G100=2))+((C10:C100=2)*(G10:G100=1)))) / SUMPRODUCT(--((C10:C100<>"")+(G10:G100<>"")>0)), "")} -> 0.86666667 | S6: {=IFERROR( SUMPRODUCT((D10:D100<>"")*(G10:G100<>"")* ((D10:D100=G10:G100)+((D10:D100=1)*(G10:G100=2))+((D10:D100=2)*(G10:G100=1)))) / SUMPRODUCT(--((D10:D100<>"")+(G10:G100<>"")>0)), "")} -> 0.8125 | T6: {=IFERROR( SUMPRODUCT((G10:G100<>"")*(E10:E100<>"")* ((G10:G100=E10:E100)+((G10:G100=1)*(E10:E100=2))+((G10:G100=2)*(E10:E100=1)))) / SUMPRODUCT(--((G10:G100<>"")+(E10:E100<>"")>0)), "")} -> 0.86666667 | U6: {=IFERROR( SUMPRODUCT((F10:F100<>"")*(G10:G100<>"")* ((F10:F100=G10:G100)+((F10:F100=1)*(G10:G100=2))+((F10:F100=2)*(G10:G100=1)))) / SUMPRODUCT(--((F10:F100<>"")+(G10:G100<>"")>0)), "")} -> 0.76470588
A7: Semantic FP Loose | C7: =COUNTIF(C20:C56,0) -> 2 | D7: =COUNTIF(D20:D56,0) -> 3 | E7: =COUNTIF(E20:E56,0) -> 2 | F7: =COUNTIF(F20:F56,0) -> 2 | G7: =COUNTIF(G20:G56,0) -> 2 | H7: =COUNTIF(H20:H56,0) -> 1 | J7: XML run 3 | K7: {=IFERROR(SUMPRODUCT((C10:C100<>"")*(H10:H100<>"")*(C10:C100=H10:H100))/SUMPRODUCT(--((C10:C100<>"")+(H10:H100<>"")>0)),"")} -> 0.75 | L7: {=IFERROR(SUMPRODUCT((H10:H100<>"")*(D10:D100<>"")*(H10:H100=D10:D100))/SUMPRODUCT(--((H10:H100<>"")+(D10:D100<>"")>0)),"")} -> 0.70588235 | M7: {=IFERROR(SUMPRODUCT((H10:H100<>"")*(E10:E100<>"")*(H10:H100=E10:E100))/SUMPRODUCT(--((H10:H100<>"")+(E10:E100<>"")>0)),"")} -> 0.75 | N7: {=IFERROR(SUMPRODUCT((F10:F100<>"")*(H10:H100<>"")*(F10:F100=H10:H100))/SUMPRODUCT(--((F10:F100<>"")+(H10:H100<>"")>0)),"")} -> 0.76470588 | O7: {=IFERROR(SUMPRODUCT((G10:G100<>"")*(H10:H100<>"")*(G10:G100=H10:H100))/SUMPRODUCT(--((G10:G100<>"")+(H10:H100<>"")>0)),"")} -> 0.75 | Q7: XML run 3 | R7: {=IFERROR( SUMPRODUCT((C10:C100<>"")*(H10:H100<>"")* ((C10:C100=H10:H100)+((C10:C100=1)*(H10:H100=2))+((C10:C100=2)*(H10:H100=1)))) / SUMPRODUCT(--((C10:C100<>"")+(H10:H100<>"")>0)), "")} -> 0.8125 | S7: {=IFERROR( SUMPRODUCT((H10:H100<>"")*(D10:D100<>"")* ((H10:H100=D10:D100)+((H10:H100=1)*(D10:D100=2))+((H10:H100=2)*(D10:D100=1)))) / SUMPRODUCT(--((H10:H100<>"")+(D10:D100<>"")>0)), "")} -> 0.76470588 | T7: {=IFERROR( SUMPRODUCT((H10:H100<>"")*(E10:E100<>"")* ((H10:H100=E10:E100)+((H10:H100=1)*(E10:E100=2))+((H10:H100=2)*(E10:E100=1)))) / SUMPRODUCT(--((H10:H100<>"")+(E10:E100<>"")>0)), "")} -> 0.8125 | U7: {=IFERROR( SUMPRODUCT((F10:F100<>"")*(H10:H100<>"")* ((F10:F100=H10:H100)+((F10:F100=1)*(H10:H100=2))+((F10:F100=2)*(H10:H100=1)))) / SUMPRODUCT(--((F10:F100<>"")+(H10:H100<>"")>0)), "")} -> 0.82352941 | V7: {=IFERROR( SUMPRODUCT((H10:H100<>"")*(G10:G100<>"")* ((H10:H100=G10:G100)+((H10:H100=1)*(G10:G100=2))+((H10:H100=2)*(G10:G100=1)))) / SUMPRODUCT(--((H10:H100<>"")+(G10:G100<>"")>0)), "")} -> 0.8125
C9: Chatbot run 1 | D9: Chatbot run 2 | E9: Chatbot run 3 | F9: XML run 1 | G9: XML run 2 | H9: XML run 3
A10: Tasks/Messages/Events | B10: Assess Risk | C10: 2 | D10: 2 | E10: 2 | F10: 2 | G10: 2 | H10: 2
B11: Receive Credit Request | C11: 2 | D11: 2 | E11: 2 | F11: 2 | G11: 2 | H11: 2
B12: Carry Out Advanced Risk Assessment | C12: 2 | D12: 2 | E12: 2 | F12: 2 | G12: 2 | H12: 2
B13: Carry Out Simple Risk Assessment | C13: 2 | D13: 2 | E13: 2 | F13: 2 | G13: 2 | H13: 2
B14: Notify Customer of Assessment Result | C14: 2 | D14: 2 | E14: 2 | F14: 2 | G14: 2 | H14: 2
B15: Organize Disbursement | C15: 2 | D15: 2 | E15: 2 | F15: 2 | G15: 2 | H15: 2
A16: Conditions/Loops/Parallel | B16: Is Risk above threshold? | C16: 2 | D16: 2 | E16: 2 | F16: 2 | G16: 2 | H16: 2
A17: Data Objects | B17: Credit Request | C17: 2 | D17: 2 | E17: 2 | F17: 2 | G17: 1 | H17: 1
B18: Assessment Result | C18: 2 | D18: 2 | E18: 2 | F18: 2 | G18: 1 | H18: 2
A20: False Positives | B20: Customer Pool | C20: 1 | D20: 1 | E20: 1 | F20: 1 | G20: 1 | H20: 1
B21: Bank Pool | C21: 1 | D21: 1 | E21: 1 | F21: 1 | G21: 1 | H21: 1
B22: Receive Assesmnet Result | C22: 1 | D22: 1 | E22: 1 | F22: 1 | G22: 1 | H22: 1
B23: Risk Managmnet Lane | C23: 0 | D23: 0 | E23: 0 | F23: 0 | G23: 0 | H23: 0
B24: Distribumnet Lane | C24: 0 | D24: 0 | F24: 0
B25: Credit Department Lane | D25: 0 | E25: 0
B26: Send Credit Request | F26: 1 | H26: 1
B27: Prepare Assessment Result | F27: 1
B28: Processing Department Lane | G28: 0
B29: Operations Lane | H29: 1

Sheet c4
A1: Semantic Percision | C1: =SUM(C3:C4) / (C3+ C4+ C7) * 100 -> 91.666667 | D1: =SUM(D3:D4) / (D3+ D4+ D7) * 100 -> 100 | E1: =SUM(E3:E4) / (E3+ E4+ E7) * 100 -> 100 | F1: =SUM(F3:F4) / (F3+ F4+ F7) * 100 -> 66.666667 | G1: =SUM(G3:G4) / (G3+ G4+ G7) * 100 -> 95.652174 | H1: =SUM(H3:H4) / (H3+ H4+ H7) * 100 -> 95.652174 | J1: Jaccard Strict | K1: Chatbot run 1 | L1: Chatbot run 2 | M1: Chatbot run 3 | N1: XML run 1 | O1: XML run 2 | P1: XML run 3 | Q1: Jaccard Loose | R1: Chatbot run 1 | S1: Chatbot run 2 | T1: Chatbot run 3 | U1: XML run 1 | V1: XML run 2 | W1: XML run 3
A2: Semantic Recall | C2: =SUM(C3:C4) / SUM(C3:C5) *100 -> 100 | D2: =SUM(D3:D4) / SUM(D3:D5) *100 -> 100 | E2: =SUM(E3:E4) / SUM(E3:E5) *100 -> 100 | F2: =SUM(F3:F4) / SUM(F3:F5) *100 -> 100 | G2: =SUM(G3:G4) / SUM(G3:G5) *100 -> 100 | H2: =SUM(H3:H4) / SUM(H3:H5) *100 -> 100 | J2: Chatbot run 1 | Q2: Chatbot run 1
A3: Semantic TP Explicit | C3: =COUNTIF(C10:C31, 2) -> 20 | D3: =COUNTIF(D10:D31, 2) -> 20 | E3: =COUNTIF(E10:E31, 2) -> 20 | F3: =COUNTIF(F10:F31, 2) -> 19 | G3: =COUNTIF(G10:G31, 2) -> 21 | H3: =COUNTIF(H10:H31, 2) -> 19 | J3: Chatbot run 2 | K3: {=IFERROR(SUMPRODUCT((C10:C100<>"")*(D10:D100<>"")*(C10:C100=D10:D100))/SUMPRODUCT(--((C10:C100<>"")+(D10:D100<>"")>0)),"")} -> 0.68965517 | Q3: Chatbot run 2 | R3: {=IFERROR( SUMPRODUCT((C10:C100<>"")*(D10:D100<>"")* ((C10:C100=D10:D100)+((C10:C100=1)*(D10:D100=2))+((C10:C100=2)*(D10:D100=1)))) / SUMPRODUCT(--((C10:C100<>"")+(D10:D100<>"")>0)), "")} -> 0.75862069
A4: Semantic TP Implicit | C4: =COUNTIF(C10:C31, 1) -> 2 | D4: =COUNTIF(D10:D31, 1) -> 2 | E4: =COUNTIF(E10:E31, 1) -> 2 | F4: =COUNTIF(F10:F31, 1) -> 3 | G4: =COUNTIF(G10:G31, 1) -> 1 | H4: =COUNTIF(H10:H31, 1) -> 3 | J4: Chatbot run 3 | K4: {=IFERROR(SUMPRODUCT((C10:C100<>"")*(E10:E100<>"")*(C10:C100=E10:E100))/SUMPRODUCT(--((C10:C100<>"")+(E10:E100<>"")>0)),"")} -> 0.625 | L4: {=IFERROR(SUMPRODUCT((E10:E100<>"")*(D10:D100<>"")*(E10:E100=D10:D100))/SUMPRODUCT(--((E10:E100<>"")+(D10:D100<>"")>0)),"")} -> 0.82758621 | Q4: Chatbot run 3 | R4: {=IFERROR( SUMPRODUCT((C10:C100<>"")*(E10:E100<>"")* ((C10:C100=E10:E100)+((C10:C100=1)*(E10:E100=2))+((C10:C100=2)*(E10:E100=1)))) / SUMPRODUCT(--((C10:C100<>"")+(E10:E100<>"")>0)), "")} -> 0.6875 | S4: {=IFERROR( SUMPRODUCT((E10:E100<>"")*(D10:D100<>"")* ((E10:E100=D10:D100)+((E10:E100=1)*(D10:D100=2))+((E10:E100=2)*(D10:D100=1)))) / SUMPRODUCT(--((E10:E100<>"")+(D10:D100<>"")>0)), "")} -> 0.89655172
A5: Semantic FN | C5: =COUNTIF(C10:C31, 0) -> 0 | D5: =COUNTIF(D10:D31, 0) -> 0 | E5: =COUNTIF(E10:E31, 0) -> 0 | F5: =COUNTIF(F10:F31, 0) -> 0 | G5: =COUNTIF(G10:G31, 0) -> 0 | H5: =COUNTIF(H10:H31, 0) -> 0 | J5: XML run 1 | K5: {=IFERROR(SUMPRODUCT((C10:C100<>"")*(F10:F100<>"")*(C10:C100=F10:F100))/SUMPRODUCT(--((C10:C100<>"")+(F10:F100<>"")>0)),"")} -> 0.62162162 | L5: {=IFERROR(SUMPRODUCT((F10:F100<>"")*(D10:D100<>"")*(F10:F100=D10:D100))/SUMPRODUCT(--((F10:F100<>"")+(D10:D100<>"")>0)),"")} -> 0.51282051 | M5: {=IFERROR(SUMPRODUCT((F10:F100<>"")*(E10:E100<>"")*(F10:F100=E10:E100))/SUMPRODUCT(--((F10:F100<>"")+(E10:E100<>"")>0)),"")} -> 0.47619048 | Q5: XML run 1 | R5: {=IFERROR( SUMPRODUCT((C10:C100<>"")*(F10:F100<>"")* ((C10:C100=F10:F100)+((C10:C100=1)*(F10:F100=2))+((C10:C100=2)*(F10:F100=1)))) / SUMPRODUCT(--((C10:C100<>"")+(F10:F100<>"")>0)), "")} -> 0.64864865 | S5: {=IFERROR( SUMPRODUCT((F10:F100<>"")*(D10:D100<>"")* ((F10:F100=D10:D100)+((F10:F100=1)*(D10:D100=2))+((F10:F100=2)*(D10:D100=1)))) / SUMPRODUCT(--((F10:F100<>"")+(D10:D100<>"")>0)), "")} -> 0.58974359 | T5: {=IFERROR( SUMPRODUCT((F10:F100<>"")*(E10:E100<>"")* ((F10:F100=E10:E100)+((F10:F100=1)*(E10:E100=2))+((F10:F100=2)*(E10:E100=1)))) / SUMPRODUCT(--((F10:F100<>"")+(E10:E100<>"")>0)), "")} -> 0.54761905
A6: Semantic FP Strict | C6: =COUNTIF(C33:C57,0) + COUNTIF(C33:C57,1) -> 3 | D6: =COUNTIF(D33:D57,0) + COUNTIF(D33:D57,1) -> 4 | E6: =COUNTIF(E33:E57,0) + COUNTIF(E33:E57,1) -> 7 | F6: =COUNTIF(F33:F57,0) + COUNTIF(F33:F57,1) -> 14 | G6: =COUNTIF(G33:G57,0) + COUNTIF(G33:G57,1) -> 3 | H6: =COUNTIF(H33:H57,0) + COUNTIF(H33:H57,1) -> 6 | J6: XML run 2 | K6: {=IFERROR(SUMPRODUCT((C10:C100<>"")*(G10:G100<>"")*(C10:C100=G10:G100))/SUMPRODUCT(--((C10:C100<>"")+(G10:G100<>"")>0)),"")} -> 0.75 | L6: {=SUMPRODUCT((D10:D100<>0)*(G10:G100<>0)) / SUMPRODUCT(((D10:D100<>0)+(G10:G100<>0)>0)*1)} -> 0.85185185 | M6: {=IFERROR(SUMPRODUCT((G10:G100<>"")*(E10:E100<>"")*(G10:G100=E10:E100))/SUMPRODUCT(--((G10:G100<>"")+(E10:E100<>"")>0)),"")} -> 0.70967742 | N6: {=IFERROR(SUMPRODUCT((G10:G100<>"")*(F10:F100<>"")*(G10:G100=F10:F100))/SUMPRODUCT(--((G10:G100<>"")+(F10:F100<>"")>0)),"")} -> 0.55263158 | Q6: XML run 2 | R6: {=IFERROR( SUMPRODUCT((C10:C100<>"")*(G10:G100<>"")* ((C10:C100=G10:G100)+((C10:C100=1)*(G10:G100=2))+((C10:C100=2)*(G10:G100=1)))) / SUMPRODUCT(--((C10:C100<>"")+(G10:G100<>"")>0)), "")} -> 0.78571429 | S6: {=IFERROR( SUMPRODUCT((D10:D100<>"")*(G10:G100<>"")* ((D10:D100=G10:G100)+((D10:D100=1)*(G10:G100=2))+((D10:D100=2)*(G10:G100=1)))) / SUMPRODUCT(--((D10:D100<>"")+(G10:G100<>"")>0)), "")} -> 0.82142857 | T6: {=IFERROR( SUMPRODUCT((G10:G100<>"")*(E10:E100<>"")* ((G10:G100=E10:E100)+((G10:G100=1)*(E10:E100=2))+((G10:G100=2)*(E10:E100=1)))) / SUMPRODUCT(--((G10:G100<>"")+(E10:E100<>"")>0)), "")} -> 0.74193548 | U6: {=IFERROR( SUMPRODUCT((F10:F100<>"")*(G10:G100<>"")* ((F10:F100=G10:G100)+((F10:F100=1)*(G10:G100=2))+((F10:F100=2)*(G10:G100=1)))) / SUMPRODUCT(--((F10:F100<>"")+(G10:G100<>"")>0)), "")} -> 0.60526316
A7: Semantic FP Loose | C7: =COUNTIF(C33:C57,0) -> 2 | D7: =COUNTIF(D33:D57,0) -> 0 | E7: =COUNTIF(E33:E57,0) -> 0 | F7: =COUNTIF(F33:F57,0) -> 11 | G7: =COUNTIF(G33:G57,0) -> 1 | H7: =COUNTIF(H33:H57,0) -> 1 | J7: XML run 3 | K7: {=IFERROR(SUMPRODUCT((C10:C100<>"")*(H10:H100<>"")*(C10:C100=H10:H100))/SUMPRODUCT(--((C10:C100<>"")+(H10:H100<>"")>0)),"")} -> 0.61290323 | L7: {=IFERROR(SUMPRODUCT((H10:H100<>"")*(D10:D100<>"")*(H10:H100=D10:D100))/SUMPRODUCT(--((H10:H100<>"")+(D10:D100<>"")>0)),"")} -> 0.64516129 | M7: {=IFERROR(SUMPRODUCT((H10:H100<>"")*(E10:E100<>"")*(H10:H100=E10:E100))/SUMPRODUCT(--((H10:H100<>"")+(E10:E100<>"")>0)),"")} -> 0.6875 | N7: {=IFERROR(SUMPRODUCT((F10:F100<>"")*(H10:H100<>"")*(F10:F100=H10:H100))/SUMPRODUCT(--((F10:F100<>"")+(H10:H100<>"")>0)),"")} -> 0.5 | O7: {=IFERROR(SUMPRODUCT((G10:G100<>"")*(H10:H100<>"")*(G10:G100=H10:H100))/SUMPRODUCT(--((G10:G100<>"")+(H10:H100<>"")>0)),"")} -> 0.7 | Q7: XML run 3 | R7: {=IFERROR( SUMPRODUCT((C10:C100<>"")*(H10:H100<>"")* ((C10:C100=H10:H100)+((C10:C100=1)*(H10:H100=2))+((C10:C100=2)*(H10:H100=1)))) / SUMPRODUCT(--((C10:C100<>"")+(H10:H100<>"")>0)), "")} -> 0.70967742 | S7: {=IFERROR( SUMPRODUCT((H10:H100<>"")*(D10:D100<>"")* ((H10:H100=D10:D100)+((H10:H100=1)*(D10:D100=2))+((H10:H100=2)*(D10:D100=1)))) / SUMPRODUCT(--((H10:H100<>"")+(D10:D100<>"")>0)), "")} -> 0.74193548 | T7: {=IFERROR( SUMPRODUCT((H10:H100<>"")*(E10:E100<>"")* ((H10:H100=E10:E100)+((H10:H100=1)*(E10:E100=2))+((H10:H100=2)*(E10:E100=1)))) / SUMPRODUCT(--((H10:H100<>"")+(E10:E100<>"")>0)), "")} -> 0.78125 | U7: {=IFERROR( SUMPRODUCT((F10:F100<>"")*(H10:H100<>"")* ((F10:F100=H10:H100)+((F10:F100=1)*(H10:H100=2))+((F10:F100=2)*(H10:H100=1)))) / SUMPRODUCT(--((F10:F100<>"")+(H10:H100<>"")>0)), "")} -> 0.6 | V7: {=IFERROR( SUMPRODUCT((H10:H100<>"")*(G10:G100<>"")* ((H10:H100=G10:G100)+((H10:H100=1)*(G10:G100=2))+((H10:H100=2)*(G10:G100=1)))) / SUMPRODUCT(--((H10:H100<>"")+(G10:G100<>"")>0)), "")} -> 0.76666667
C9: Chatbot run 1 | D9: Chatbot run 2 | E9: Chatbot run 3 | F9: XML run 1 | G9: XML run 2 | H9: XML run 3
A10: Tasks/Messages/Events | B10: Read Order | C10: 2 | D10: 2 | E10: 2 | F10: 2 | G10: 2 | H10: 2
B11: Select Next Product from Order | C11: 2 | D11: 2 | E11: 2 | F11: 2 | G11: 2 | H11: 2
B12: Check if Product is in Stock | C12: 1 | D12: 2 | E12: 2 | F12: 1 | G12: 2 | H12: 2
B13: Withdraw Product from Warehouse | C13: 2 | D13: 2 | E13: 2 | F13: 2 | G13: 2 | H13: 2
B14: Reorder Product from Wholesaler | C14: 2 | D14: 2 | E14: 2 | F14: 2 | G14: 2 | H14: 2
B15: Product Arrived | C15: 2 | D15: 1 | E15: 2 | F15: 2 | G15: 2 | H15: 2
B16: Register Product | C16: 2 | D16: 2 | E16: 2 | F16: 2 | G16: 2 | H16: 2
B17: Wait for 10 days | C17: 2 | D17: 2 | E17: 2 | F17: 2 | G17: 2 | H17: 2
B18: Demand Delivery Delay Penalty | C18: 2 | D18: 2 | E18: 2 | F18: 2 | G18: 2 | H18: 2
B19: Check if Whole Order is Ready for Shipment | C19: 2 | D19: 2 | E19: 2 | F19: 2 | G19: 2 | H19: 1
B20: Request Courier | C20: 2 | D20: 2 | E20: 2 | F20: 2 | G20: 2 | H20: 2
B21: Pack Products | C21: 2 | D21: 2 | E21: 2 | F21: 2 | G21: 2 | H21: 2
B22: Ship Order | C22: 2 | D22: 2 | E22: 2 | F22: 2 | G22: 2 | H22: 2
A23: Conditions/Loops/Parallel: | B23: Parallel (Request Courier || Pack Products ) | C23: 2 | D23: 2 | E23: 2 | F23: 2 | G23: 2 | H23: 2
B24: Is product in stock? | C24: 2 | D24: 2 | E24: 2 | F24: 2 | G24: 2 | H24: 2
B25: Did Product Arrived before 10 days? | C25: 2 | D25: 2 | E25: 1 | F25: 2 | G25: 2 | H25: 2
B26: Is order ready for shipment? | C26: 2 | D26: 2 | E26: 2 | F26: 2 | G26: 2 | H26: 2
B27: For Each Product from Order Loop | C27: 2 | D27: 2 | E27: 2 | F27: 2 | G27: 2 | H27: 2
A28: Data Objects | B28: Order Management System | C28: 1 | D28: 1 | E28: 1 | F28: 1 | G28: 1 | H28: 1
B29: Order | C29: 2 | D29: 2 | E29: 2 | F29: 2 | G29: 2 | H29: 2
B30: Product | C30: 2 | D30: 2 | E30: 2 | F30: 2 | G30: 2 | H30: 1
B31: Stock Management System | C31: 2 | D31: 2 | E31: 2 | F31: 1 | G31: 2 | H31: 2
A33: False Positives | B33: Courier Request DO | C33: 1
B34: Pool Retailer | C34: 0 | F34: 0
B35: Lane Order and Inventory Management | C35: 0 | F35: 0
B36: Wholesaler Pool | D36: 1 | E36: 1 | F36: 1 | G36: 1 | H36: 1
B37: Warehouse Record DO | D37: 1 | E37: 1
B38: Courier Request DO | D38: 1 | E38: 1
B39: Packed Products DO | D39: 1 | E39: 1
B40: Warehouse Record DO | E40: 1
B41: Storage Management Lane | E41: 1 | H41: 1
B42: Logistics Lane | E42: 1 | H42: 1
...

Sheet c5
A1: Semantic Percision | C1: =SUM(C3:C4) / (C3+ C4+ C7) * 100 -> 100 | D1: =SUM(D3:D4) / (D3+ D4+ D7) * 100 -> 100 | E1: =SUM(E3:E4) / (E3+ E4+ E7) * 100 -> 100 | F1: =SUM(F3:F4) / (F3+ F4+ F7) * 100 -> 100 | G1: =SUM(G3:G4) / (G3+ G4+ G7) * 100 -> 92.857143 | H1: =SUM(H3:H4) / (H3+ H4+ H7) * 100 -> 92.857143 | J1: Jaccard Strict | K1: Chatbot run 1 | L1: Chatbot run 2 | M1: Chatbot run 3 | N1: XML run 1 | O1: XML run 2 | P1: XML run 3 | Q1: Jaccard Loose | R1: Chatbot run 1 | S1: Chatbot run 2 | T1: Chatbot run 3 | U1: XML run 1 | V1: XML run 2 | W1: XML run 3
A2: Semantic Recall | C2: =SUM(C3:C4) / SUM(C3:C5) *100 -> 100 | D2: =SUM(D3:D4) / SUM(D3:D5) *100 -> 100 | E2: =SUM(E3:E4) / SUM(E3:E5) *100 -> 100 | F2: =SUM(F3:F4) / SUM(F3:F5) *100 -> 100 | G2: =SUM(G3:G4) / SUM(G3:G5) *100 -> 100 | H2: =SUM(H3:H4) / SUM(H3:H5) *100 -> 100 | J2: Chatbot run 1 | Q2: Chatbot run 1
A3: Semantic TP Explicit | C3: =COUNTIF(C10:C22, 2) -> 13 | D3: =COUNTIF(D10:D22, 2) -> 13 | E3: =COUNTIF(E10:E22, 2) -> 13 | F3: =COUNTIF(F10:F22, 2) -> 11 | G3: =COUNTIF(G10:G22, 2) -> 13 | H3: =COUNTIF(H10:H22, 2) -> 13 | J3: Chatbot run 2 | K3: {=IFERROR(SUMPRODUCT((C10:C100<>"")*(D10:D100<>"")*(C10:C100=D10:D100))/SUMPRODUCT(--((C10:C100<>"")+(D10:D100<>"")>0)),"")} -> 0.93333333 | Q3: Chatbot run 2 | R3: {=IFERROR( SUMPRODUCT((C10:C100<>"")*(D10:D100<>"")* ((C10:C100=D10:D100)+((C10:C100=1)*(D10:D100=2))+((C10:C100=2)*(D10:D100=1)))) / SUMPRODUCT(--((C10:C100<>"")+(D10:D100<>"")>0)), "")} -> 0.93333333
A4: Semantic TP Implicit | C4: =COUNTIF(C10:C22, 1) -> 0 | D4: =COUNTIF(D10:D22, 1) -> 0 | E4: =COUNTIF(E10:E22, 1) -> 0 | F4: =COUNTIF(F10:F22, 1) -> 2 | G4: =COUNTIF(G10:G22, 1) -> 0 | H4: =COUNTIF(H10:H22, 1) -> 0 | J4: Chatbot run 3 | K4: {=IFERROR(SUMPRODUCT((C10:C100<>"")*(E10:E100<>"")*(C10:C100=E10:E100))/SUMPRODUCT(--((C10:C100<>"")+(E10:E100<>"")>0)),"")} -> 0.93333333 | L4: {=IFERROR(SUMPRODUCT((E10:E100<>"")*(D10:D100<>"")*(E10:E100=D10:D100))/SUMPRODUCT(--((E10:E100<>"")+(D10:D100<>"")>0)),"")} -> 1 | Q4: Chatbot run 3 | R4: {=IFERROR( SUMPRODUCT((C10:C100<>"")*(E10:E100<>"")* ((C10:C100=E10:E100)+((C10:C100=1)*(E10:E100=2))+((C10:C100=2)*(E10:E100=1)))) / SUMPRODUCT(--((C10:C100<>"")+(E10:E100<>"")>0)), "")} -> 0.93333333 | S4: {=IFERROR( SUMPRODUCT((E10:E100<>"")*(D10:D100<>"")* ((E10:E100=D10:D100)+((E10:E100=1)*(D10:D100=2))+((E10:E100=2)*(D10:D100=1)))) / SUMPRODUCT(--((E10:E100<>"")+(D10:D100<>"")>0)), "")} -> 1
A5: Semantic FN | C5: =COUNTIF(C10:C22, 0) -> 0 | D5: =COUNTIF(D10:D22, 0) -> 0 | E5: =COUNTIF(E10:E22, 0) -> 0 | F5: =COUNTIF(F10:F22, 0) -> 0 | G5: =COUNTIF(G10:G22, 0) -> 0 | H5: =COUNTIF(H10:H22, 0) -> 0 | J5: XML run 1 | K5: {=IFERROR(SUMPRODUCT((C10:C100<>"")*(F10:F100<>"")*(C10:C100=F10:F100))/SUMPRODUCT(--((C10:C100<>"")+(F10:F100<>"")>0)),"")} -> 0.73333333 | L5: {=IFERROR(SUMPRODUCT((F10:F100<>"")*(D10:D100<>"")*(F10:F100=D10:D100))/SUMPRODUCT(--((F10:F100<>"")+(D10:D100<>"")>0)),"")} -> 0.6875 | M5: {=IFERROR(SUMPRODUCT((F10:F100<>"")*(E10:E100<>"")*(F10:F100=E10:E100))/SUMPRODUCT(--((F10:F100<>"")+(E10:E100<>"")>0)),"")} -> 0.6875 | Q5: XML run 1 | R5: {=IFERROR( SUMPRODUCT((C10:C100<>"")*(F10:F100<>"")* ((C10:C100=F10:F100)+((C10:C100=1)*(F10:F100=2))+((C10:C100=2)*(F10:F100=1)))) / SUMPRODUCT(--((C10:C100<>"")+(F10:F100<>"")>0)), "")} -> 0.86666667 | S5: {=IFERROR( SUMPRODUCT((F10:F100<>"")*(D10:D100<>"")* ((F10:F100=D10:D100)+((F10:F100=1)*(D10:D100=2))+((F10:F100=2)*(D10:D100=1)))) / SUMPRODUCT(--((F10:F100<>"")+(D10:D100<>"")>0)), "")} -> 0.8125 | T5: {=IFERROR( SUMPRODUCT((F10:F100<>"")*(E10:E100<>"")* ((F10:F100=E10:E100)+((F10:F100=1)*(E10:E100=2))+((F10:F100=2)*(E10:E100=1)))) / SUMPRODUCT(--((F10:F100<>"")+(E10:E100<>"")>0)), "")} -> 0.8125
A6: Semantic FP Strict | C6: =COUNTIF(C24:C29,0) + COUNTIF(C24:C29,1) -> 1 | D6: =COUNTIF(D24:D29,0) + COUNTIF(D24:D29,1) -> 2 | E6: =COUNTIF(E24:E29,0) + COUNTIF(E24:E29,1) -> 2 | F6: =COUNTIF(F24:F29,0) + COUNTIF(F24:F29,1) -> 1 | G6: =COUNTIF(G24:G29,0) + COUNTIF(G24:G29,1) -> 1 | H6: =COUNTIF(H24:H29,0) + COUNTIF(H24:H29,1) -> 2 | J6: XML run 2 | K6: {=IFERROR(SUMPRODUCT((C10:C100<>"")*(G10:G100<>"")*(C10:C100=G10:G100))/SUMPRODUCT(--((C10:C100<>"")+(G10:G100<>"")>0)),"")} -> 0.86666667 | L6: {=SUMPRODUCT((D10:D100<>0)*(G10:G100<>0)) / SUMPRODUCT(((D10:D100<>0)+(G10:G100<>0)>0)*1)} -> 0.86666667 | M6: {=IFERROR(SUMPRODUCT((G10:G100<>"")*(E10:E100<>"")*(G10:G100=E10:E100))/SUMPRODUCT(--((G10:G100<>"")+(E10:E100<>"")>0)),"")} -> 0.8125 | N6: {=IFERROR(SUMPRODUCT((G10:G100<>"")*(F10:F100<>"")*(G10:G100=F10:F100))/SUMPRODUCT(--((G10:G100<>"")+(F10:F100<>"")>0)),"")} -> 0.73333333 | Q6: XML run 2 | R6: {=IFERROR( SUMPRODUCT((C10:C100<>"")*(G10:G100<>"")* ((C10:C100=G10:G100)+((C10:C100=1)*(G10:G100=2))+((C10:C100=2)*(G10:G100=1)))) / SUMPRODUCT(--((C10:C100<>"")+(G10:G100<>"")>0)), "")} -> 0.86666667 | S6: {=IFERROR( SUMPRODUCT((D10:D100<>"")*(G10:G100<>"")* ((D10:D100=G10:G100)+((D10:D100=1)*(G10:G100=2))+((D10:D100=2)*(G10:G100=1)))) / SUMPRODUCT(--((D10:D100<>"")+(G10:G100<>"")>0)), "")} -> 0.8125 | T6: {=IFERROR( SUMPRODUCT((G10:G100<>"")*(E10:E100<>"")* ((G10:G100=E10:E100)+((G10:G100=1)*(E10:E100=2))+((G10:G100=2)*(E10:E100=1)))) / SUMPRODUCT(--((G10:G100<>"")+(E10:E100<>"")>0)), "")} -> 0.8125 | U6: {=IFERROR( SUMPRODUCT((F10:F100<>"")*(G10:G100<>"")* ((F10:F100=G10:G100)+((F10:F100=1)*(G10:G100=2))+((F10:F100=2)*(G10:G100=1)))) / SUMPRODUCT(--((F10:F100<>"")+(G10:G100<>"")>0)), "")} -> 0.86666667
A7: Semantic FP Loose | C7: =COUNTIF(C24:C29,0) -> 0 | D7: =COUNTIF(D24:D29,0) -> 0 | E7: =COUNTIF(E24:E29,0) -> 0 | F7: =COUNTIF(F24:F29,0) -> 0 | G7: =COUNTIF(G24:G29,0) -> 1 | H7: =COUNTIF(H24:H29,0) -> 1 | J7: XML run 3 | K7: {=IFERROR(SUMPRODUCT((C10:C100<>"")*(H10:H100<>"")*(C10:C100=H10:H100))/SUMPRODUCT(--((C10:C100<>"")+(H10:H100<>"")>0)),"")} -> 0.8125 | L7: {=IFERROR(SUMPRODUCT((H10:H100<>"")*(D10:D100<>"")*(H10:H100=D10:D100))/SUMPRODUCT(--((H10:H100<>"")+(D10:D100<>"")>0)),"")} -> 0.76470588 | M7: {=IFERROR(SUMPRODUCT((H10:H100<>"")*(E10:E100<>"")*(H10:H100=E10:E100))/SUMPRODUCT(--((H10:H100<>"")+(E10:E100<>"")>0)),"")} -> 0.76470588 | N7: {=IFERROR(SUMPRODUCT((F10:F100<>"")*(H10:H100<>"")*(F10:F100=H10:H100))/SUMPRODUCT(--((F10:F100<>"")+(H10:H100<>"")>0)),"")} -> 0.6875 | O7: {=IFERROR(SUMPRODUCT((G10:G100<>"")*(H10:H100<>"")*(G10:G100=H10:H100))/SUMPRODUCT(--((G10:G100<>"")+(H10:H100<>"")>0)),"")} -> 0.8125 | Q7: XML run 3 | R7: {=IFERROR( SUMPRODUCT((C10:C100<>"")*(H10:H100<>"")* ((C10:C100=H10:H100)+((C10:C100=1)*(H10:H100=2))+((C10:C100=2)*(H10:H100=1)))) / SUMPRODUCT(--((C10:C100<>"")+(H10:H100<>"")>0)), "")} -> 0.8125 | S7: {=IFERROR( SUMPRODUCT((H10:H100<>"")*(D10:D100<>"")* ((H10:H100=D10:D100)+((H10:H100=1)*(D10:D100=2))+((H10:H100=2)*(D10:D100=1)))) / SUMPRODUCT(--((H10:H100<>"")+(D10:D100<>"")>0)), "")} -> 0.76470588 | T7: {=IFERROR( SUMPRODUCT((H10:H100<>"")*(E10:E100<>"")* ((H10:H100=E10:E100)+((H10:H100=1)*(E10:E100=2))+((H10:H100=2)*(E10:E100=1)))) / SUMPRODUCT(--((H10:H100<>"")+(E10:E100<>"")>0)), "")} -> 0.76470588 | U7: {=IFERROR( SUMPRODUCT((F10:F100<>"")*(H10:H100<>"")* ((F10:F100=H10:H100)+((F10:F100=1)*(H10:H100=2))+((F10:F100=2)*(H10:H100=1)))) / SUMPRODUCT(--((F10:F100<>"")+(H10:H100<>"")>0)), "")} -> 0.8125 | V7: {=IFERROR( SUMPRODUCT((H10:H100<>"")*(G10:G100<>"")* ((H10:H100=G10:G100)+((H10:H100=1)*(G10:G100=2))+((H10:H100=2)*(G10:G100=1)))) / SUMPRODUCT(--((H10:H100<>"")+(G10:G100<>"")>0)), "")} -> 0.8125
C9: Chatbot run 1 | D9: Chatbot run 2 | E9: Chatbot run 3 | F9: XML run 1 | G9: XML run 2 | H9: XML run 3
A10: Pools | B10: Tribunal | C10: 2 | D10: 2 | E10: 2 | F10: 2 | G10: 2 | H10: 2
B11: Owner | C11: 2 | D11: 2 | E11: 2 | F11: 2 | G11: 2 | H11: 2
A12: Tasks/Messages/Events | B12: Receive Compensation Request from Owner | C12: 2 | D12: 2 | E12: 2 | F12: 2 | G12: 2 | H12: 2
B13: Retrieve Premises File | C13: 2 | D13: 2 | E13: 2 | F13: 2 | G13: 2 | H13: 2
B14: Check Request Acceptability and Compliance | C14: 2 | D14: 2 | E14: 2 | F14: 2 | G14: 2 | H14: 2
B15: Allocate Hearing Date | C15: 2 | D15: 2 | E15: 2 | F15: 2 | G15: 2 | H15: 2
B16: Produce / Send Fees Notice | C16: 2 | D16: 2 | E16: 2 | F16: 2 | G16: 2 | H16: 2
B17: Receive Fees Payment | C17: 2 | D17: 2 | E17: 2 | F17: 2 | G17: 2 | H17: 2
B18: Reassess Document Compliance | C18: 2 | D18: 2 | E18: 2 | F18: 2 | G18: 2 | H18: 2
A19: Conditions/Loops/Parallel: | B19: Fees Paid with Request? | C19: 2 | D19: 2 | E19: 2 | F19: 2 | G19: 2 | H19: 2
A20: Data Objects | B20: Compensation Request | C20: 2 | D20: 2 | E20: 2 | F20: 2 | G20: 2 | H20: 2
B21: Premises File | C21: 2 | D21: 2 | E21: 2 | F21: 1 | G21: 2 | H21: 2
B22: Fees Notice | C22: 2 | D22: 2 | E22: 2 | F22: 1 | G22: 2 | H22: 2
A24: False Positives | B24: Pay Fees | C24: 1 | D24: 1 | E24: 1
B25: Payment Record DO | D25: 1 | E25: 1
B26: Prepare Compensation Request | F26: 1
B27: Owner Lane in Tribunal | G27: 0
B28: Premises File Store | H28: 0
B29: Submit compensation request | H29: 1

Sheet c6
A1: Semantic Percision | C1: =SUM(C3:C4) / (C3+ C4+ C7) * 100 -> 100 | D1: =SUM(D3:D4) / (D3+ D4+ D7) * 100 -> 100 | E1: =SUM(E3:E4) / (E3+ E4+ E7) * 100 -> 92.307692 | F1: =SUM(F3:F4) / (F3+ F4+ F7) * 100 -> 72.222222 | G1: =SUM(G3:G4) / (G3+ G4+ G7) * 100 -> 92.857143 | H1: =SUM(H3:H4) / (H3+ H4+ H7) * 100 -> 86.666667 | J1: Jaccard Strict | K1: Chatbot run 1 | L1: Chatbot run 2 | M1: Chatbot run 3 | N1: XML run 1 | O1: XML run 2 | P1: XML run 3 | Q1: Jaccard Loose | R1: Chatbot run 1 | S1: Chatbot run 2 | T1: Chatbot run 3 | U1: XML run 1 | V1: XML run 2 | W1: XML run 3
A2: Semantic Recall | C2: =SUM(C3:C4) / SUM(C3:C5) *100 -> 85.714286 | D2: =SUM(D3:D4) / SUM(D3:D5) *100 -> 85.714286 | E2: =SUM(E3:E4) / SUM(E3:E5) *100 -> 85.714286 | F2: =SUM(F3:F4) / SUM(F3:F5) *100 -> 92.857143 | G2: =SUM(G3:G4) / SUM(G3:G5) *100 -> 92.857143 | H2: =SUM(H3:H4) / SUM(H3:H5) *100 -> 92.857143 | J2: Chatbot run 1 | Q2: Chatbot run 1
A3: Semantic TP Explicit | C3: =COUNTIF(C10:C23, 2) -> 11 | D3: =COUNTIF(D10:D23, 2) -> 11 | E3: =COUNTIF(E10:E23, 2) -> 10 | F3: =COUNTIF(F10:F23, 2) -> 12 | G3: =COUNTIF(G10:G23, 2) -> 12 | H3: =COUNTIF(H10:H23, 2) -> 11 | J3: Chatbot run 2 | K3: {=IFERROR(SUMPRODUCT((C10:C100<>"")*(D10:D100<>"")*(C10:C100=D10:D100))/SUMPRODUCT(--((C10:C100<>"")+(D10:D100<>"")>0)),"")} -> 0.91666667 | Q3: Chatbot run 2 | R3: {=IFERROR( SUMPRODUCT((C10:C100<>"")*(D10:D100<>"")* ((C10:C100=D10:D100)+((C10:C100=1)*(D10:D100=2))+((C10:C100=2)*(D10:D100=1)))) / SUMPRODUCT(--((C10:C100<>"")+(D10:D100<>"")>0)), "")} -> 0.91666667
A4: Semantic TP Implicit | C4: =COUNTIF(C10:C23, 1) -> 1 | D4: =COUNTIF(D10:D23, 1) -> 1 | E4: =COUNTIF(E10:E23, 1) -> 2 | F4: =COUNTIF(F10:F23, 1) -> 1 | G4: =COUNTIF(G10:G23, 1) -> 1 | H4: =COUNTIF(H10:H23, 1) -> 2 | J4: Chatbot run 3 | K4: {=IFERROR(SUMPRODUCT((C10:C100<>"")*(E10:E100<>"")*(C10:C100=E10:E100))/SUMPRODUCT(--((C10:C100<>"")+(E10:E100<>"")>0)),"")} -> 0.88 | L4: {=IFERROR(SUMPRODUCT((E10:E100<>"")*(D10:D100<>"")*(E10:E100=D10:D100))/SUMPRODUCT(--((E10:E100<>"")+(D10:D100<>"")>0)),"")} -> 0.80769231 | Q4: Chatbot run 3 | R4: {=IFERROR( SUMPRODUCT((C10:C100<>"")*(E10:E100<>"")* ((C10:C100=E10:E100)+((C10:C100=1)*(E10:E100=2))+((C10:C100=2)*(E10:E100=1)))) / SUMPRODUCT(--((C10:C100<>"")+(E10:E100<>"")>0)), "")} -> 0.92 | S4: {=IFERROR( SUMPRODUCT((E10:E100<>"")*(D10:D100<>"")* ((E10:E100=D10:D100)+((E10:E100=1)*(D10:D100=2))+((E10:E100=2)*(D10:D100=1)))) / SUMPRODUCT(--((E10:E100<>"")+(D10:D100<>"")>0)), "")} -> 0.84615385
